Workbook

Sheet moment_rate
B1: =58*14 -> 812 | M1: =M507 -> 0.04031838 | U1: =U507 -> 0.25982093 | AC1: =AC507 -> 0.0074493433
B2: =LOG10(58*14) -> 2.909556 | M2: =M507 -> 0.04031838 | U2: =U507 -> 0.25982093 | AC2: =AC507 -> 0.0074493433
E4: out2 file prob | J4: =SUM(J7:J1207) -> 99.998211 | K4: 0.01 | L4: =SUM(L7:L2004)*$K$4 -> 2.9627125e+21 | M4: =1/M7 -> 0.0009352164 | P4: =SUM(P7:P1004)*K4 -> 2.7738932e+21 | R4: For TE model | W4: =SUM(W7:W863) -> 3.8200478e+20 | Y4: For maxMag model | Z4: =SUM(Z7:Z863) -> 100.00236 | AA4: =SUM(AA7:AA863) -> 4.2528241e+26
D6: Mag | E6: rate M for pure char | F6: rate M for YC85 | I6: mag | J6: char pdf | K6: cumulative density | L6: moment * pdf | M6: N(M) for YC model | N6: char eqk (# of events) | P6: moment in Char | R6: mag | S6: exponentail density | T6: cumulative 1 | U6: N(M) for TE model | V6: moment | W6: moment*density | Y6: mag | Z6: Truncated normal pdf | AA6: moment*density*dm | AB6: C CDF | AC6: N(M) for maxmag
A7: b | B7: 0.9 | D7: ='Out2 for pureChar'!$A7 -> 5.05 | E7: ='Out2 for pureChar'!$B7 -> 0 | F7: ='out2 for YC'!$B7 -> 0.0068924883 | I7: 0.005 | J7: =IF($I7>$B$23,0,1)*IF($I7<($B$23-$B$21),$B$10*EXP(-$B$10*($I7-$B$8)),$B$10*EXP(-$B$10*($B$23-$B$20-$B$21-$B$8)))/(1-EXP(-$B$10*($B$23-$B$21-$B$8)))*(1/(1+$B$24)) -> 2.0509523 | K7: =$J7*K$4+K8 -> 0.99998211 | L7: =$V7*$J7 -> 2.3412919e+16 | M7: =$K7/$L$4*$B$18 -> 1069.2712 | N7: =IF($I7>$B$23,0,1)*IF($I7<($B$23-$B$21),0,M7) -> 0 | O7: =IF($I7>$B$23,0,1)*IF($I7<($B$23-$B$33),0,1)*IF($I7<($B$23-$B$21),$B$10*EXP(-$B$10*($I7-$B$8)),$B$10*EXP(-$B$10*($B$23-$B$20-$B$21-$B$8)))/(1-EXP(-$B$10*($B$23-$B$21-$B$8)))*(1/(1+$B$24))*($B$18/(SUM($L$7:$L$105)*0.05)) -> 0 | P7: =IF($I7>$B$23,0,1)*IF($I7<($B$23-$B$21),0,1)*$L7 -> 0 | R7: =$I7 -> 0.005 | S7: =IF($I7<$B$23+0.01,$B$10*EXP(-$B$10*($I7-$B$8))/(1-EXP(-$B$10*($B$23-$B$8))),0) -> 2.0509654 | T7: =T8+$S7*0.01 -> 0.99998211 | U7: =T7*$B$18/$W$4 -> 8292.9415 | V7: =10^(1.5*$I7+16.05) -> 1.1415633e+16 | W7: =$S7*$V7*0.01 -> 2.3413068e+14 | X7: =(1-EXP(-$B$10*($B$9-0.5-$B$8))+$B$10/2*EXP(-$B$10*($B$9-1.5-$B$8))) -> 1.0000102 | Y7: =I7 -> 0.005 | Z7: =IF(AND($Y7<$B$9+$B$27*$B$28,$Y7>$B$9-$B$27*$B$28),NORMDIST($Y7,$B$9,$B$27,0) / (2*NORMDIST($B$28,0,1,1)-1),0) -> 0 | AA7: =$V7*$Z7*$K$4 -> 0 | AB7: =Z7*$K$4+AB8 -> 1.0000236 | AC7: =$AB7*$B$18/$AA$4 -> 0.0074493433
A8: min mag | B8: 0 | D8: ='Out2 for pureChar'!$A8 -> 5.15 | E8: ='Out2 for pureChar'!$B8 -> 0 | F8: ='out2 for YC'!$B8 -> 0.0050387207 | I8: =I7+0.01 -> 0.015 | J8: =IF($I8>$B$23,0,1)*IF($I8<($B$23-$B$21),$B$10*EXP(-$B$10*($I8-$B$8)),$B$10*EXP(-$B$10*($B$23-$B$20-$B$21-$B$8)))/(1-EXP(-$B$10*($B$23-$B$21-$B$8)))*(1/(1+$B$24)) -> 2.0088872 | K8: =$J8*K$4+K9 -> 0.97947258 | L8: =$V8*$J8 -> 2.3738625e+16 | M8: =$K8/$L$4*$B$18 -> 1047.3406 | N8: =IF($I8>$B$23,0,1)*IF($I8<($B$23-$B$21),0,M8) -> 0 | O8: =IF($I8>$B$23,0,1)*IF($I8<($B$23-$B$33),0,1)*IF($I8<($B$23-$B$21),$B$10*EXP(-$B$10*($I8-$B$8)),$B$10*EXP(-$B$10*($B$23-$B$20-$B$21-$B$8)))/(1-EXP(-$B$10*($B$23-$B$21-$B$8)))*(1/(1+$B$24))*($B$18/(SUM($L$7:$L$105)*0.05)) -> 0 | P8: =IF($I8>$B$23,0,1)*IF($I8<($B$23-$B$21),0,1)*$L8 -> 0 | R8: =$I8 -> 0.015 | S8: =IF($I8<$B$23+0.01,$B$10*EXP(-$B$10*($I8-$B$8))/(1-EXP(-$B$10*($B$23-$B$8))),0) -> 2.0089 | T8: =T9+$S8*0.01 -> 0.97947246 | U8: =T8*$B$18/$W$4 -> 8122.8531 | V8: =10^(1.5*$I8+16.05) -> 1.1816803e+16 | W8: =$S8*$V8*0.01 -> 2.3738776e+14 | Y8: =I8 -> 0.015 | Z8: =IF(AND($Y8<$B$9+$B$27*$B$28,$Y8>$B$9-$B$27*$B$28),NORMDIST($Y8,$B$9,$B$27,0) / (2*NORMDIST($B$28,0,1,1)-1),0) -> 0 | AA8: =$V8*$Z8*$K$4 -> 0 | AB8: =Z8*$K$4+AB9 -> 1.0000236 | AC8: =$AB8*$B$18/$AA$4 -> 0.0074493433
A9: m char | B9: 7 | D9: ='Out2 for pureChar'!$A9 -> 5.25 | E9: ='Out2 for pureChar'!$B9 -> 0 | F9: ='out2 for YC'!$B9 -> 0.004095626 | I9: =I8+0.01 -> 0.025 | J9: =IF($I9>$B$23,0,1)*IF($I9<($B$23-$B$21),$B$10*EXP(-$B$10*($I9-$B$8)),$B$10*EXP(-$B$10*($B$23-$B$20-$B$21-$B$8)))/(1-EXP(-$B$10*($B$23-$B$21-$B$8)))*(1/(1+$B$24)) -> 1.9676849 | K9: =$J9*K$4+K10 -> 0.95938371 | L9: =$V9*$J9 -> 2.4068862e+16 | M9: =$K9/$L$4*$B$18 -> 1025.8598 | N9: =IF($I9>$B$23,0,1)*IF($I9<($B$23-$B$21),0,M9) -> 0 | O9: =IF($I9>$B$23,0,1)*IF($I9<($B$23-$B$33),0,1)*IF($I9<($B$23-$B$21),$B$10*EXP(-$B$10*($I9-$B$8)),$B$10*EXP(-$B$10*($B$23-$B$20-$B$21-$B$8)))/(1-EXP(-$B$10*($B$23-$B$21-$B$8)))*(1/(1+$B$24))*($B$18/(SUM($L$7:$L$105)*0.05)) -> 0 | P9: =IF($I9>$B$23,0,1)*IF($I9<($B$23-$B$21),0,1)*$L9 -> 0 | R9: =$I9 -> 0.025 | S9: =IF($I9<$B$23+0.01,$B$10*EXP(-$B$10*($I9-$B$8))/(1-EXP(-$B$10*($B$23-$B$8))),0) -> 1.9676975 | T9: =T10+$S9*0.01 -> 0.95938346 | U9: =T9*$B$18/$W$4 -> 7956.2532 | V9: =10^(1.5*$I9+16.05) -> 1.2232071e+16 | W9: =$S9*$V9*0.01 -> 2.4069016e+14 | Y9: =I9 -> 0.025 | Z9: =IF(AND($Y9<$B$9+$B$27*$B$28,$Y9>$B$9-$B$27*$B$28),NORMDIST($Y9,$B$9,$B$27,0) / (2*NORMDIST($B$28,0,1,1)-1),0) -> 0 | AA9: =$V9*$Z9*$K$4 -> 0 | AB9: =Z9*$K$4+AB10 -> 1.0000236 | AC9: =$AB9*$B$18/$AA$4 -> 0.0074493433
A10: beta | B10: =$B$7*LN(10) -> 2.0723266 | D10: ='Out2 for pureChar'!$A10 -> 5.35 | E10: ='Out2 for pureChar'!$B10 -> 0 | F10: ='out2 for YC'!$B10 -> 0.0033290498 | I10: =I9+0.01 -> 0.035 | J10: =IF($I10>$B$23,0,1)*IF($I10<($B$23-$B$21),$B$10*EXP(-$B$10*($I10-$B$8)),$B$10*EXP(-$B$10*($B$23-$B$20-$B$21-$B$8)))/(1-EXP(-$B$10*($B$23-$B$21-$B$8)))*(1/(1+$B$24)) -> 1.9273277 | K10: =$J10*K$4+K11 -> 0.93970686 | L10: =$V10*$J10 -> 2.4403693e+16 | M10: =$K10/$L$4*$B$18 -> 1004.8195 | N10: =IF($I10>$B$23,0,1)*IF($I10<($B$23-$B$21),0,M10) -> 0 | O10: =IF($I10>$B$23,0,1)*IF($I10<($B$23-$B$33),0,1)*IF($I10<($B$23-$B$21),$B$10*EXP(-$B$10*($I10-$B$8)),$B$10*EXP(-$B$10*($B$23-$B$20-$B$21-$B$8)))/(1-EXP(-$B$10*($B$23-$B$21-$B$8)))*(1/(1+$B$24))*($B$18/(SUM($L$7:$L$105)*0.05)) -> 0 | P10: =IF($I10>$B$23,0,1)*IF($I10<($B$23-$B$21),0,1)*$L10 -> 0 | R10: =$I10 -> 0.035 | S10: =IF($I10<$B$23+0.01,$B$10*EXP(-$B$10*($I10-$B$8))/(1-EXP(-$B$10*($B$23-$B$8))),0) -> 1.92734 | T10: =T11+$S10*0.01 -> 0.93970648 | U10: =T10*$B$18/$W$4 -> 7793.0703 | V10: =10^(1.5*$I10+16.05) -> 1.2661933e+16 | W10: =$S10*$V10*0.01 -> 2.4403849e+14 | Y10: =I10 -> 0.035 | Z10: =IF(AND($Y10<$B$9+$B$27*$B$28,$Y10>$B$9-$B$27*$B$28),NORMDIST($Y10,$B$9,$B$27,0) / (2*NORMDIST($B$28,0,1,1)-1),0) -> 0 | AA10: =$V10*$Z10*$K$4 -> 0 | AB10: =Z10*$K$4+AB11 -> 1.0000236 | AC10: =$AB10*$B$18/$AA$4 -> 0.0074493433
D11: ='Out2 for pureChar'!$A11 -> 5.45 | E11: ='Out2 for pureChar'!$B11 -> 0 | F11: ='out2 for YC'!$B11 -> 0.0027059532 | I11: =I10+0.01 -> 0.045 | J11: =IF($I11>$B$23,0,1)*IF($I11<($B$23-$B$21),$B$10*EXP(-$B$10*($I11-$B$8)),$B$10*EXP(-$B$10*($B$23-$B$20-$B$21-$B$8)))/(1-EXP(-$B$10*($B$23-$B$21-$B$8)))*(1/(1+$B$24)) -> 1.8877981 | K11: =$J11*K$4+K12 -> 0.92043359 | L11: =$V11*$J11 -> 2.4743182e+16 | M11: =$K11/$L$4*$B$18 -> 984.21078 | N11: =IF($I11>$B$23,0,1)*IF($I11<($B$23-$B$21),0,M11) -> 0 | O11: =IF($I11>$B$23,0,1)*IF($I11<($B$23-$B$33),0,1)*IF($I11<($B$23-$B$21),$B$10*EXP(-$B$10*($I11-$B$8)),$B$10*EXP(-$B$10*($B$23-$B$20-$B$21-$B$8)))/(1-EXP(-$B$10*($B$23-$B$21-$B$8)))*(1/(1+$B$24))*($B$18/(SUM($L$7:$L$105)*0.05)) -> 0 | P11: =IF($I11>$B$23,0,1)*IF($I11<($B$23-$B$21),0,1)*$L11 -> 0 | R11: =$I11 -> 0.045 | S11: =IF($I11<$B$23+0.01,$B$10*EXP(-$B$10*($I11-$B$8))/(1-EXP(-$B$10*($B$23-$B$8))),0) -> 1.8878102 | T11: =T12+$S11*0.01 -> 0.92043308 | U11: =T11*$B$18/$W$4 -> 7633.2343 | V11: =10^(1.5*$I11+16.05) -> 1.31069e+16 | W11: =$S11*$V11*0.01 -> 2.474334e+14 | Y11: =I11 -> 0.045 | Z11: =IF(AND($Y11<$B$9+$B$27*$B$28,$Y11>$B$9-$B$27*$B$28),NORMDIST($Y11,$B$9,$B$27,0) / (2*NORMDIST($B$28,0,1,1)-1),0) -> 0 | AA11: =$V11*$Z11*$K$4 -> 0 | AB11: =Z11*$K$4+AB12 -> 1.0000236 | AC11: =$AB11*$B$18/$AA$4 -> 0.0074493433
A12: sliprate (mm/yr) | B12: 11 | D12: ='Out2 for pureChar'!$A12 -> 5.55 | E12: ='Out2 for pureChar'!$B12 -> 0 | F12: ='out2 for YC'!$B12 -> 0.0021994814 | I12: =I11+0.01 -> 0.055 | J12: =IF($I12>$B$23,0,1)*IF($I12<($B$23-$B$21),$B$10*EXP(-$B$10*($I12-$B$8)),$B$10*EXP(-$B$10*($B$23-$B$20-$B$21-$B$8)))/(1-EXP(-$B$10*($B$23-$B$21-$B$8)))*(1/(1+$B$24)) -> 1.8490794 | K12: =$J12*K$4+K13 -> 0.9015556 | L12: =$V12*$J12 -> 2.5087394e+16 | M12: =$K12/$L$4*$B$18 -> 964.02473 | N12: =IF($I12>$B$23,0,1)*IF($I12<($B$23-$B$21),0,M12) -> 0 | O12: =IF($I12>$B$23,0,1)*IF($I12<($B$23-$B$33),0,1)*IF($I12<($B$23-$B$21),$B$10*EXP(-$B$10*($I12-$B$8)),$B$10*EXP(-$B$10*($B$23-$B$20-$B$21-$B$8)))/(1-EXP(-$B$10*($B$23-$B$21-$B$8)))*(1/(1+$B$24))*($B$18/(SUM($L$7:$L$105)*0.05)) -> 0 | P12: =IF($I12>$B$23,0,1)*IF($I12<($B$23-$B$21),0,1)*$L12 -> 0 | R12: =$I12 -> 0.055 | S12: =IF($I12<$B$23+0.01,$B$10*EXP(-$B$10*($I12-$B$8))/(1-EXP(-$B$10*($B$23-$B$8))),0) -> 1.8490912 | T12: =T13+$S12*0.01 -> 0.90155498 | U12: =T12*$B$18/$W$4 -> 7476.6765 | V12: =10^(1.5*$I12+16.05) -> 1.3567505e+16 | W12: =$S12*$V12*0.01 -> 2.5087554e+14 | Y12: =I12 -> 0.055 | Z12: =IF(AND($Y12<$B$9+$B$27*$B$28,$Y12>$B$9-$B$27*$B$28),NORMDIST($Y12,$B$9,$B$27,0) / (2*NORMDIST($B$28,0,1,1)-1),0) -> 0 | AA12: =$V12*$Z12*$K$4 -> 0 | AB12: =Z12*$K$4+AB13 -> 1.0000236 | AC12: =$AB12*$B$18/$AA$4 -> 0.0074493433
A13: length (km) | B13: 80 | D13: ='Out2 for pureChar'!$A13 -> 5.65 | E13: ='Out2 for pureChar'!$B13 -> 0 | F13: ='out2 for YC'!$B13 -> 0.0017878056 | I13: =I12+0.01 -> 0.065 | J13: =IF($I13>$B$23,0,1)*IF($I13<($B$23-$B$21),$B$10*EXP(-$B$10*($I13-$B$8)),$B$10*EXP(-$B$10*($B$23-$B$20-$B$21-$B$8)))/(1-EXP(-$B$10*($B$23-$B$21-$B$8)))*(1/(1+$B$24)) -> 1.8111547 | K13: =$J13*K$4+K14 -> 0.88306481 | L13: =$V13*$J13 -> 2.5436395e+16 | M13: =$K13/$L$4*$B$18 -> 944.25271 | N13: =IF($I13>$B$23,0,1)*IF($I13<($B$23-$B$21),0,M13) -> 0 | O13: =IF($I13>$B$23,0,1)*IF($I13<($B$23-$B$33),0,1)*IF($I13<($B$23-$B$21),$B$10*EXP(-$B$10*($I13-$B$8)),$B$10*EXP(-$B$10*($B$23-$B$20-$B$21-$B$8)))/(1-EXP(-$B$10*($B$23-$B$21-$B$8)))*(1/(1+$B$24))*($B$18/(SUM($L$7:$L$105)*0.05)) -> 0 | P13: =IF($I13>$B$23,0,1)*IF($I13<($B$23-$B$21),0,1)*$L13 -> 0 | R13: =$I13 -> 0.065 | S13: =IF($I13<$B$23+0.01,$B$10*EXP(-$B$10*($I13-$B$8))/(1-EXP(-$B$10*($B$23-$B$8))),0) -> 1.8111663 | T13: =T14+$S13*0.01 -> 0.88306407 | U13: =T13*$B$18/$W$4 -> 7323.3297 | V13: =10^(1.5*$I13+16.05) -> 1.4044297e+16 | W13: =$S13*$V13*0.01 -> 2.5436557e+14 | Y13: =I13 -> 0.065 | Z13: =IF(AND($Y13<$B$9+$B$27*$B$28,$Y13>$B$9-$B$27*$B$28),NORMDIST($Y13,$B$9,$B$27,0) / (2*NORMDIST($B$28,0,1,1)-1),0) -> 0 | AA13: =$V13*$Z13*$K$4 -> 0 | AB13: =Z13*$K$4+AB14 -> 1.0000236 | AC13: =$AB13*$B$18/$AA$4 -> 0.0074493433
A14: seismo thick (km) | B14: 12 | D14: ='Out2 for pureChar'!$A14 -> 5.75 | E14: ='Out2 for pureChar'!$B14 -> 0 | F14: ='out2 for YC'!$B14 -> 0.0014531829 | I14: =I13+0.01 -> 0.075 | J14: =IF($I14>$B$23,0,1)*IF($I14<($B$23-$B$21),$B$10*EXP(-$B$10*($I14-$B$8)),$B$10*EXP(-$B$10*($B$23-$B$20-$B$21-$B$8)))/(1-EXP(-$B$10*($B$23-$B$21-$B$8)))*(1/(1+$B$24)) -> 1.7740079 | K14: =$J14*K$4+K15 -> 0.86495326 | L14: =$V14*$J14 -> 2.579025e+16 | M14: =$K14/$L$4*$B$18 -> 924.8862 | N14: =IF($I14>$B$23,0,1)*IF($I14<($B$23-$B$21),0,M14) -> 0 | O14: =IF($I14>$B$23,0,1)*IF($I14<($B$23-$B$33),0,1)*IF($I14<($B$23-$B$21),$B$10*EXP(-$B$10*($I14-$B$8)),$B$10*EXP(-$B$10*($B$23-$B$20-$B$21-$B$8)))/(1-EXP(-$B$10*($B$23-$B$21-$B$8)))*(1/(1+$B$24))*($B$18/(SUM($L$7:$L$105)*0.05)) -> 0 | P14: =IF($I14>$B$23,0,1)*IF($I14<($B$23-$B$21),0,1)*$L14 -> 0 | R14: =$I14 -> 0.075 | S14: =IF($I14<$B$23+0.01,$B$10*EXP(-$B$10*($I14-$B$8))/(1-EXP(-$B$10*($B$23-$B$8))),0) -> 1.7740192 | T14: =T15+$S14*0.01 -> 0.86495241 | U14: =T14*$B$18/$W$4 -> 7173.128 | V14: =10^(1.5*$I14+16.05) -> 1.4537844e+16 | W14: =$S14*$V14*0.01 -> 2.5790415e+14 | Y14: =I14 -> 0.075 | Z14: =IF(AND($Y14<$B$9+$B$27*$B$28,$Y14>$B$9-$B$27*$B$28),NORMDIST($Y14,$B$9,$B$27,0) / (2*NORMDIST($B$28,0,1,1)-1),0) -> 0 | AA14: =$V14*$Z14*$K$4 -> 0 | AB14: =Z14*$K$4+AB15 -> 1.0000236 | AC14: =$AB14*$B$18/$AA$4 -> 0.0074493433
A15: dip | B15: 90 | D15: ='Out2 for pureChar'!$A15 -> 5.85 | E15: ='Out2 for pureChar'!$B15 -> 0 | F15: ='out2 for YC'!$B15 -> 0.0011811914 | I15: =I14+0.01 -> 0.085 | J15: =IF($I15>$B$23,0,1)*IF($I15<($B$23-$B$21),$B$10*EXP(-$B$10*($I15-$B$8)),$B$10*EXP(-$B$10*($B$23-$B$20-$B$21-$B$8)))/(1-EXP(-$B$10*($B$23-$B$21-$B$8)))*(1/(1+$B$24)) -> 1.737623 | K15: =$J15*K$4+K16 -> 0.84721318 | L15: =$V15*$J15 -> 2.6149028e+16 | M15: =$K15/$L$4*$B$18 -> 905.91691 | N15: =IF($I15>$B$23,0,1)*IF($I15<($B$23-$B$21),0,M15) -> 0 | O15: =IF($I15>$B$23,0,1)*IF($I15<($B$23-$B$33),0,1)*IF($I15<($B$23-$B$21),$B$10*EXP(-$B$10*($I15-$B$8)),$B$10*EXP(-$B$10*($B$23-$B$20-$B$21-$B$8)))/(1-EXP(-$B$10*($B$23-$B$21-$B$8)))*(1/(1+$B$24))*($B$18/(SUM($L$7:$L$105)*0.05)) -> 0 | P15: =IF($I15>$B$23,0,1)*IF($I15<($B$23-$B$21),0,1)*$L15 -> 0 | R15: =$I15 -> 0.085 | S15: =IF($I15<$B$23+0.01,$B$10*EXP(-$B$10*($I15-$B$8))/(1-EXP(-$B$10*($B$23-$B$8))),0) -> 1.7376341 | T15: =T16+$S15*0.01 -> 0.84721221 | U15: =T15*$B$18/$W$4 -> 7026.007 | V15: =10^(1.5*$I15+16.05) -> 1.5048735e+16 | W15: =$S15*$V15*0.01 -> 2.6149195e+14 | Y15: =I15 -> 0.085 | Z15: =IF(AND($Y15<$B$9+$B$27*$B$28,$Y15>$B$9-$B$27*$B$28),NORMDIST($Y15,$B$9,$B$27,0) / (2*NORMDIST($B$28,0,1,1)-1),0) -> 0 | AA15: =$V15*$Z15*$K$4 -> 0 | AB15: =Z15*$K$4+AB16 -> 1.0000236 | AC15: =$AB15*$B$18/$AA$4 -> 0.0074493433
A16: down-dip width (km) | B16: =B14/SIN(B15*PI()/180) -> 12 | D16: ='Out2 for pureChar'!$A16 -> 5.95 | E16: ='Out2 for pureChar'!$B16 -> 0 | F16: ='out2 for YC'!$B16 -> 0.00096010844 | I16: =I15+0.01 -> 0.095 | J16: =IF($I16>$B$23,0,1)*IF($I16<($B$23-$B$21),$B$10*EXP(-$B$10*($I16-$B$8)),$B$10*EXP(-$B$10*($B$23-$B$20-$B$21-$B$8)))/(1-EXP(-$B$10*($B$23-$B$21-$B$8)))*(1/(1+$B$24)) -> 1.7019843 | K16: =$J16*K$4+K17 -> 0.82983695 | L16: =$V16*$J16 -> 2.6512798e+16 | M16: =$K16/$L$4*$B$18 -> 887.33667 | N16: =IF($I16>$B$23,0,1)*IF($I16<($B$23-$B$21),0,M16) -> 0 | O16: =IF($I16>$B$23,0,1)*IF($I16<($B$23-$B$33),0,1)*IF($I16<($B$23-$B$21),$B$10*EXP(-$B$10*($I16-$B$8)),$B$10*EXP(-$B$10*($B$23-$B$20-$B$21-$B$8)))/(1-EXP(-$B$10*($B$23-$B$21-$B$8)))*(1/(1+$B$24))*($B$18/(SUM($L$7:$L$105)*0.05)) -> 0 | P16: =IF($I16>$B$23,0,1)*IF($I16<($B$23-$B$21),0,1)*$L16 -> 0 | R16: =$I16 -> 0.095 | S16: =IF($I16<$B$23+0.01,$B$10*EXP(-$B$10*($I16-$B$8))/(1-EXP(-$B$10*($B$23-$B$8))),0) -> 1.7019952 | T16: =T17+$S16*0.01 -> 0.82983587 | U16: =T16*$B$18/$W$4 -> 6881.9035 | V16: =10^(1.5*$I16+16.05) -> 1.557758e+16 | W16: =$S16*$V16*0.01 -> 2.6512967e+14 | Y16: =I16 -> 0.095 | Z16: =IF(AND($Y16<$B$9+$B$27*$B$28,$Y16>$B$9-$B$27*$B$28),NORMDIST($Y16,$B$9,$B$27,0) / (2*NORMDIST($B$28,0,1,1)-1),0) -> 0 | AA16: =$V16*$Z16*$K$4 -> 0 | AB16: =Z16*$K$4+AB17 -> 1.0000236 | AC16: =$AB16*$B$18/$AA$4 -> 0.0074493433
A17: mu | B17: 300000000000 | D17: ='Out2 for pureChar'!$A17 -> 6.05 | E17: ='Out2 for pureChar'!$B17 -> 0 | F17: ='out2 for YC'!$B17 -> 0.00078040544 | I17: =I16+0.01 -> 0.105 | J17: =IF($I17>$B$23,0,1)*IF($I17<($B$23-$B$21),$B$10*EXP(-$B$10*($I17-$B$8)),$B$10*EXP(-$B$10*($B$23-$B$20-$B$21-$B$8)))/(1-EXP(-$B$10*($B$23-$B$21-$B$8)))*(1/(1+$B$24)) -> 1.6670766 | K17: =$J17*K$4+K18 -> 0.81281711 | L17: =$V17*$J17 -> 2.6881627e+16 | M17: =$K17/$L$4*$B$18 -> 869.13752 | N17: =IF($I17>$B$23,0,1)*IF($I17<($B$23-$B$21),0,M17) -> 0 | O17: =IF($I17>$B$23,0,1)*IF($I17<($B$23-$B$33),0,1)*IF($I17<($B$23-$B$21),$B$10*EXP(-$B$10*($I17-$B$8)),$B$10*EXP(-$B$10*($B$23-$B$20-$B$21-$B$8)))/(1-EXP(-$B$10*($B$23-$B$21-$B$8)))*(1/(1+$B$24))*($B$18/(SUM($L$7:$L$105)*0.05)) -> 0 | P17: =IF($I17>$B$23,0,1)*IF($I17<($B$23-$B$21),0,1)*$L17 -> 0 | R17: =$I17 -> 0.105 | S17: =IF($I17<$B$23+0.01,$B$10*EXP(-$B$10*($I17-$B$8))/(1-EXP(-$B$10*($B$23-$B$8))),0) -> 1.6670872 | T17: =T18+$S17*0.01 -> 0.81281592 | U17: =T17*$B$18/$W$4 -> 6740.7555 | V17: =10^(1.5*$I17+16.05) -> 1.612501e+16 | W17: =$S17*$V17*0.01 -> 2.6881799e+14 | Y17: =I17 -> 0.105 | Z17: =IF(AND($Y17<$B$9+$B$27*$B$28,$Y17>$B$9-$B$27*$B$28),NORMDIST($Y17,$B$9,$B$27,0) / (2*NORMDIST($B$28,0,1,1)-1),0) -> 0 | AA17: =$V17*$Z17*$K$4 -> 0 | AB17: =Z17*$K$4+AB18 -> 1.0000236 | AC17: =$AB17*$B$18/$AA$4 -> 0.0074493433
A18: moment rate | B18: =B$12*B$13*B$16*B$17*1000000000 -> 3.168e+24 | D18: ='Out2 for pureChar'!$A18 -> 6.15 | E18: ='Out2 for pureChar'!$B18 -> 0 | F18: ='out2 for YC'!$B18 -> 0.00063433736 | I18: =I17+0.01 -> 0.115 | J18: =IF($I18>$B$23,0,1)*IF($I18<($B$23-$B$21),$B$10*EXP(-$B$10*($I18-$B$8)),$B$10*EXP(-$B$10*($B$23-$B$20-$B$21-$B$8)))/(1-EXP(-$B$10*($B$23-$B$21-$B$8)))*(1/(1+$B$24)) -> 1.6328848 | K18: =$J18*K$4+K19 -> 0.79614634 | L18: =$V18*$J18 -> 2.7255588e+16 | M18: =$K18/$L$4*$B$18 -> 851.31163 | N18: =IF($I18>$B$23,0,1)*IF($I18<($B$23-$B$21),0,M18) -> 0 | O18: =IF($I18>$B$23,0,1)*IF($I18<($B$23-$B$33),0,1)*IF($I18<($B$23-$B$21),$B$10*EXP(-$B$10*($I18-$B$8)),$B$10*EXP(-$B$10*($B$23-$B$20-$B$21-$B$8)))/(1-EXP(-$B$10*($B$23-$B$21-$B$8)))*(1/(1+$B$24))*($B$18/(SUM($L$7:$L$105)*0.05)) -> 0 | P18: =IF($I18>$B$23,0,1)*IF($I18<($B$23-$B$21),0,1)*$L18 -> 0 | R18: =$I18 -> 0.115 | S18: =IF($I18<$B$23+0.01,$B$10*EXP(-$B$10*($I18-$B$8))/(1-EXP(-$B$10*($B$23-$B$8))),0) -> 1.6328953 | T18: =T19+$S18*0.01 -> 0.79614505 | U18: =T18*$B$18/$W$4 -> 6602.5024 | V18: =10^(1.5*$I18+16.05) -> 1.6691678e+16 | W18: =$S18*$V18*0.01 -> 2.7255762e+14 | Y18: =I18 -> 0.115 | Z18: =IF(AND($Y18<$B$9+$B$27*$B$28,$Y18>$B$9-$B$27*$B$28),NORMDIST($Y18,$B$9,$B$27,0) / (2*NORMDIST($B$28,0,1,1)-1),0) -> 0 | AA18: =$V18*$Z18*$K$4 -> 0 | AB18: =Z18*$K$4+AB19 -> 1.0000236 | AC18: =$AB18*$B$18/$AA$4 -> 0.0074493433
A19: char model: | D19: ='Out2 for pureChar'!$A19 -> 6.25 | E19: ='Out2 for pureChar'!$B19 -> 0 | F19: ='out2 for YC'!$B19 -> 0.00051560876 | I19: =I18+0.01 -> 0.125 | J19: =IF($I19>$B$23,0,1)*IF($I19<($B$23-$B$21),$B$10*EXP(-$B$10*($I19-$B$8)),$B$10*EXP(-$B$10*($B$23-$B$20-$B$21-$B$8)))/(1-EXP(-$B$10*($B$23-$B$21-$B$8)))*(1/(1+$B$24)) -> 1.5993943 | K19: =$J19*K$4+K20 -> 0.7798175 | L19: =$V19*$J19 -> 2.7634751e+16 | M19: =$K19/$L$4*$B$18 -> 833.85135 | N19: =IF($I19>$B$23,0,1)*IF($I19<($B$23-$B$21),0,M19) -> 0 | O19: =IF($I19>$B$23,0,1)*IF($I19<($B$23-$B$33),0,1)*IF($I19<($B$23-$B$21),$B$10*EXP(-$B$10*($I19-$B$8)),$B$10*EXP(-$B$10*($B$23-$B$20-$B$21-$B$8)))/(1-EXP(-$B$10*($B$23-$B$21-$B$8)))*(1/(1+$B$24))*($B$18/(SUM($L$7:$L$105)*0.05)) -> 0 | P19: =IF($I19>$B$23,0,1)*IF($I19<($B$23-$B$21),0,1)*$L19 -> 0 | R19: =$I19 -> 0.125 | S19: =IF($I19<$B$23+0.01,$B$10*EXP(-$B$10*($I19-$B$8))/(1-EXP(-$B$10*($B$23-$B$8))),0) -> 1.5994046 | T19: =T20+$S19*0.01 -> 0.7798161 | U19: =T19*$B$18/$W$4 -> 6467.085 | V19: =10^(1.5*$I19+16.05) -> 1.727826e+16 | W19: =$S19*$V19*0.01 -> 2.7634927e+14 | Y19: =I19 -> 0.125 | Z19: =IF(AND($Y19<$B$9+$B$27*$B$28,$Y19>$B$9-$B$27*$B$28),NORMDIST($Y19,$B$9,$B$27,0) / (2*NORMDIST($B$28,0,1,1)-1),0) -> 0 | AA19: =$V19*$Z19*$K$4 -> 0 | AB19: =Z19*$K$4+AB20 -> 1.0000236 | AC19: =$AB19*$B$18/$AA$4 -> 0.0074493433
A20: delta m1 (default 1) | B20: 1 | D20: ='Out2 for pureChar'!$A20 -> 6.35 | E20: ='Out2 for pureChar'!$B20 -> 0 | F20: ='out2 for YC'!$B20 -> 0.00041910254 | I20: =I19+0.01 -> 0.135 | J20: =IF($I20>$B$23,0,1)*IF($I20<($B$23-$B$21),$B$10*EXP(-$B$10*($I20-$B$8)),$B$10*EXP(-$B$10*($B$23-$B$20-$B$21-$B$8)))/(1-EXP(-$B$10*($B$23-$B$21-$B$8)))*(1/(1+$B$24)) -> 1.5665907 | K20: =$J20*K$4+K21 -> 0.76382355 | L20: =$V20*$J20 -> 2.8019189e+16 | M20: =$K20/$L$4*$B$18 -> 816.74918 | N20: =IF($I20>$B$23,0,1)*IF($I20<($B$23-$B$21),0,M20) -> 0 | O20: =IF($I20>$B$23,0,1)*IF($I20<($B$23-$B$33),0,1)*IF($I20<($B$23-$B$21),$B$10*EXP(-$B$10*($I20-$B$8)),$B$10*EXP(-$B$10*($B$23-$B$20-$B$21-$B$8)))/(1-EXP(-$B$10*($B$23-$B$21-$B$8)))*(1/(1+$B$24))*($B$18/(SUM($L$7:$L$105)*0.05)) -> 0 | P20: =IF($I20>$B$23,0,1)*IF($I20<($B$23-$B$21),0,1)*$L20 -> 0 | R20: =$I20 -> 0.135 | S20: =IF($I20<$B$23+0.01,$B$10*EXP(-$B$10*($I20-$B$8))/(1-EXP(-$B$10*($B$23-$B$8))),0) -> 1.5666007 | T20: =T21+$S20*0.01 -> 0.76382205 | U20: =T20*$B$18/$W$4 -> 6334.4449 | V20: =10^(1.5*$I20+16.05) -> 1.7885455e+16 | W20: =$S20*$V20*0.01 -> 2.8019368e+14 | Y20: =I20 -> 0.135 | Z20: =IF(AND($Y20<$B$9+$B$27*$B$28,$Y20>$B$9-$B$27*$B$28),NORMDIST($Y20,$B$9,$B$27,0) / (2*NORMDIST($B$28,0,1,1)-1),0) -> 0 | AA20: =$V20*$Z20*$K$4 -> 0 | AB20: =Z20*$K$4+AB21 -> 1.0000236 | AC20: =$AB20*$B$18/$AA$4 -> 0.0074493433
A21: delta m2 (default 0.5) | B21: 0.5 | D21: ='Out2 for pureChar'!$A21 -> 6.45 | E21: ='Out2 for pureChar'!$B21 -> 0 | F21: ='out2 for YC'!$B21 -> 0.00034065933 | I21: =I20+0.01 -> 0.145 | J21: =IF($I21>$B$23,0,1)*IF($I21<($B$23-$B$21),$B$10*EXP(-$B$10*($I21-$B$8)),$B$10*EXP(-$B$10*($B$23-$B$20-$B$21-$B$8)))/(1-EXP(-$B$10*($B$23-$B$21-$B$8)))*(1/(1+$B$24)) -> 1.5344599 | K21: =$J21*K$4+K22 -> 0.74815765 | L21: =$V21*$J21 -> 2.8408974e+16 | M21: =$K21/$L$4*$B$18 -> 799.99777 | N21: =IF($I21>$B$23,0,1)*IF($I21<($B$23-$B$21),0,M21) -> 0 | O21: =IF($I21>$B$23,0,1)*IF($I21<($B$23-$B$33),0,1)*IF($I21<($B$23-$B$21),$B$10*EXP(-$B$10*($I21-$B$8)),$B$10*EXP(-$B$10*($B$23-$B$20-$B$21-$B$8)))/(1-EXP(-$B$10*($B$23-$B$21-$B$8)))*(1/(1+$B$24))*($B$18/(SUM($L$7:$L$105)*0.05)) -> 0 | P21: =IF($I21>$B$23,0,1)*IF($I21<($B$23-$B$21),0,1)*$L21 -> 0 | R21: =$I21 -> 0.145 | S21: =IF($I21<$B$23+0.01,$B$10*EXP(-$B$10*($I21-$B$8))/(1-EXP(-$B$10*($B$23-$B$8))),0) -> 1.5344697 | T21: =T22+$S21*0.01 -> 0.74815604 | U21: =T21*$B$18/$W$4 -> 6204.5253 | V21: =10^(1.5*$I21+16.05) -> 1.8513989e+16 | W21: =$S21*$V21*0.01 -> 2.8409156e+14 | Y21: =I21 -> 0.145 | Z21: =IF(AND($Y21<$B$9+$B$27*$B$28,$Y21>$B$9-$B$27*$B$28),NORMDIST($Y21,$B$9,$B$27,0) / (2*NORMDIST($B$28,0,1,1)-1),0) -> 0 | AA21: =$V21*$Z21*$K$4 -> 0 | AB21: =Z21*$K$4+AB22 -> 1.0000236 | AC21: =$AB21*$B$18/$AA$4 -> 0.0074493433
A22: delta m3 (default 0.25) | B22: 0.25 | D22: ='Out2 for pureChar'!$A22 -> 6.55 | E22: ='Out2 for pureChar'!$B22 -> 2.2141246e-05 | F22: ='out2 for YC'!$B22 -> 0.0002768983 | I22: =I21+0.01 -> 0.155 | J22: =IF($I22>$B$23,0,1)*IF($I22<($B$23-$B$21),$B$10*EXP(-$B$10*($I22-$B$8)),$B$10*EXP(-$B$10*($B$23-$B$20-$B$21-$B$8)))/(1-EXP(-$B$10*($B$23-$B$21-$B$8)))*(1/(1+$B$24)) -> 1.5029881 | K22: =$J22*K$4+K23 -> 0.73281305 | L22: =$V22*$J22 -> 2.8804183e+16 | M22: =$K22/$L$4*$B$18 -> 783.58994 | N22: =IF($I22>$B$23,0,1)*IF($I22<($B$23-$B$21),0,M22) -> 0 | O22: =IF($I22>$B$23,0,1)*IF($I22<($B$23-$B$33),0,1)*IF($I22<($B$23-$B$21),$B$10*EXP(-$B$10*($I22-$B$8)),$B$10*EXP(-$B$10*($B$23-$B$20-$B$21-$B$8)))/(1-EXP(-$B$10*($B$23-$B$21-$B$8)))*(1/(1+$B$24))*($B$18/(SUM($L$7:$L$105)*0.05)) -> 0 | P22: =IF($I22>$B$23,0,1)*IF($I22<($B$23-$B$21),0,1)*$L22 -> 0 | R22: =$I22 -> 0.155 | S22: =IF($I22<$B$23+0.01,$B$10*EXP(-$B$10*($I22-$B$8))/(1-EXP(-$B$10*($B$23-$B$8))),0) -> 1.5029977 | T22: =T23+$S22*0.01 -> 0.73281135 | U22: =T22*$B$18/$W$4 -> 6077.2704 | V22: =10^(1.5*$I22+16.05) -> 1.9164611e+16 | W22: =$S22*$V22*0.01 -> 2.8804366e+14 | Y22: =I22 -> 0.155 | Z22: =IF(AND($Y22<$B$9+$B$27*$B$28,$Y22>$B$9-$B$27*$B$28),NORMDIST($Y22,$B$9,$B$27,0) / (2*NORMDIST($B$28,0,1,1)-1),0) -> 0 | AA22: =$V22*$Z22*$K$4 -> 0 | AB22: =Z22*$K$4+AB23 -> 1.0000236 | AC22: =$AB22*$B$18/$AA$4 -> 0.0074493433
A23: mmax +delta m3 | B23: =B$9+B$22 -> 7.25 | D23: ='Out2 for pureChar'!$A23 -> 6.65 | E23: ='Out2 for pureChar'!$B23 -> 0.00037407587 | F23: ='out2 for YC'!$B23 -> 0.00022507139 | I23: =I22+0.01 -> 0.165 | J23: =IF($I23>$B$23,0,1)*IF($I23<($B$23-$B$21),$B$10*EXP(-$B$10*($I23-$B$8)),$B$10*EXP(-$B$10*($B$23-$B$20-$B$21-$B$8)))/(1-EXP(-$B$10*($B$23-$B$21-$B$8)))*(1/(1+$B$24)) -> 1.4721618 | K23: =$J23*K$4+K24 -> 0.71778316 | L23: =$V23*$J23 -> 2.9204889e+16 | M23: =$K23/$L$4*$B$18 -> 767.51863 | N23: =IF($I23>$B$23,0,1)*IF($I23<($B$23-$B$21),0,M23) -> 0 | O23: =IF($I23>$B$23,0,1)*IF($I23<($B$23-$B$33),0,1)*IF($I23<($B$23-$B$21),$B$10*EXP(-$B$10*($I23-$B$8)),$B$10*EXP(-$B$10*($B$23-$B$20-$B$21-$B$8)))/(1-EXP(-$B$10*($B$23-$B$21-$B$8)))*(1/(1+$B$24))*($B$18/(SUM($L$7:$L$105)*0.05)) -> 0 | P23: =IF($I23>$B$23,0,1)*IF($I23<($B$23-$B$21),0,1)*$L23 -> 0 | R23: =$I23 -> 0.165 | S23: =IF($I23<$B$23+0.01,$B$10*EXP(-$B$10*($I23-$B$8))/(1-EXP(-$B$10*($B$23-$B$8))),0) -> 1.4721712 | T23: =T24+$S23*0.01 -> 0.71778137 | U23: =T23*$B$18/$W$4 -> 5952.6254 | V23: =10^(1.5*$I23+16.05) -> 1.9838097e+16 | W23: =$S23*$V23*0.01 -> 2.9205075e+14 | Y23: =I23 -> 0.165 | Z23: =IF(AND($Y23<$B$9+$B$27*$B$28,$Y23>$B$9-$B$27*$B$28),NORMDIST($Y23,$B$9,$B$27,0) / (2*NORMDIST($B$28,0,1,1)-1),0) -> 0 | AA23: =$V23*$Z23*$K$4 -> 0 | AB23: =Z23*$K$4+AB24 -> 1.0000236 | AC23: =$AB23*$B$18/$AA$4 -> 0.0074493433
A24: c | B24: =$B$10*$B$21*EXP(-$B$10*($B$23-$B$20-$B$21-$B$8))/(1-EXP(-$B$10*($B$23-$B$21-$B$8))) -> 6.9251402e-06 | D24: ='Out2 for pureChar'!$A24 -> 6.75 | E24: ='Out2 for pureChar'!$B24 -> 0.00076109353 | F24: ='out2 for YC'!$B24 -> 0.00096634704 | I24: =I23+0.01 -> 0.175 | J24: =IF($I24>$B$23,0,1)*IF($I24<($B$23-$B$21),$B$10*EXP(-$B$10*($I24-$B$8)),$B$10*EXP(-$B$10*($B$23-$B$20-$B$21-$B$8)))/(1-EXP(-$B$10*($B$23-$B$21-$B$8)))*(1/(1+$B$24)) -> 1.4419678 | K24: =$J24*K$4+K25 -> 0.70306155 | L24: =$V24*$J24 -> 2.9611169e+16 | M24: =$K24/$L$4*$B$18 -> 751.77695 | N24: =IF($I24>$B$23,0,1)*IF($I24<($B$23-$B$21),0,M24) -> 0 | O24: =IF($I24>$B$23,0,1)*IF($I24<($B$23-$B$33),0,1)*IF($I24<($B$23-$B$21),$B$10*EXP(-$B$10*($I24-$B$8)),$B$10*EXP(-$B$10*($B$23-$B$20-$B$21-$B$8)))/(1-EXP(-$B$10*($B$23-$B$21-$B$8)))*(1/(1+$B$24))*($B$18/(SUM($L$7:$L$105)*0.05)) -> 0 | P24: =IF($I24>$B$23,0,1)*IF($I24<($B$23-$B$21),0,1)*$L24 -> 0 | R24: =$I24 -> 0.175 | S24: =IF($I24<$B$23+0.01,$B$10*EXP(-$B$10*($I24-$B$8))/(1-EXP(-$B$10*($B$23-$B$8))),0) -> 1.441977 | T24: =T25+$S24*0.01 -> 0.70305966 | U24: =T24*$B$18/$W$4 -> 5830.5369 | V24: =10^(1.5*$I24+16.05) -> 2.053525e+16 | W24: =$S24*$V24*0.01 -> 2.9611358e+14 | Y24: =I24 -> 0.175 | Z24: =IF(AND($Y24<$B$9+$B$27*$B$28,$Y24>$B$9-$B$27*$B$28),NORMDIST($Y24,$B$9,$B$27,0) / (2*NORMDIST($B$28,0,1,1)-1),0) -> 0 | AA24: =$V24*$Z24*$K$4 -> 0 | AB24: =Z24*$K$4+AB25 -> 1.0000236 | AC24: =$AB24*$B$18/$AA$4 -> 0.0074493433
B25: =1/$B$24 -> 144401.41 | D25: ='Out2 for pureChar'!$A25 -> 6.85 | E25: ='Out2 for pureChar'!$B25 -> 0.0012120594 | F25: ='out2 for YC'!$B25 -> 0.0014809869 | I25: =I24+0.01 -> 0.185 | J25: =IF($I25>$B$23,0,1)*IF($I25<($B$23-$B$21),$B$10*EXP(-$B$10*($I25-$B$8)),$B$10*EXP(-$B$10*($B$23-$B$20-$B$21-$B$8)))/(1-EXP(-$B$10*($B$23-$B$21-$B$8)))*(1/(1+$B$24)) -> 1.412393 | K25: =$J25*K$4+K26 -> 0.68864187 | L25: =$V25*$J25 -> 3.0023102e+16 | M25: =$K25/$L$4*$B$18 -> 736.35812 | N25: =IF($I25>$B$23,0,1)*IF($I25<($B$23-$B$21),0,M25) -> 0 | O25: =IF($I25>$B$23,0,1)*IF($I25<($B$23-$B$33),0,1)*IF($I25<($B$23-$B$21),$B$10*EXP(-$B$10*($I25-$B$8)),$B$10*EXP(-$B$10*($B$23-$B$20-$B$21-$B$8)))/(1-EXP(-$B$10*($B$23-$B$21-$B$8)))*(1/(1+$B$24))*($B$18/(SUM($L$7:$L$105)*0.05)) -> 0 | P25: =IF($I25>$B$23,0,1)*IF($I25<($B$23-$B$21),0,1)*$L25 -> 0 | R25: =$I25 -> 0.185 | S25: =IF($I25<$B$23+0.01,$B$10*EXP(-$B$10*($I25-$B$8))/(1-EXP(-$B$10*($B$23-$B$8))),0) -> 1.412402 | T25: =T26+$S25*0.01 -> 0.68863989 | U25: =T25*$B$18/$W$4 -> 5710.9525 | V25: =10^(1.5*$I25+16.05) -> 2.1256903e+16 | W25: =$S25*$V25*0.01 -> 3.0023293e+14 | Y25: =I25 -> 0.185 | Z25: =IF(AND($Y25<$B$9+$B$27*$B$28,$Y25>$B$9-$B$27*$B$28),NORMDIST($Y25,$B$9,$B$27,0) / (2*NORMDIST($B$28,0,1,1)-1),0) -> 0 | AA25: =$V25*$Z25*$K$4 -> 0 | AB25: =Z25*$K$4+AB26 -> 1.0000236 | AC25: =$AB25*$B$18/$AA$4 -> 0.0074493433
A26: mm paramax model | D26: ='Out2 for pureChar'!$A26 -> 6.95 | E26: ='Out2 for pureChar'!$B26 -> 0.0015109255 | F26: ='out2 for YC'!$B26 -> 0.0014809869 | I26: =I25+0.01 -> 0.195 | J26: =IF($I26>$B$23,0,1)*IF($I26<($B$23-$B$21),$B$10*EXP(-$B$10*($I26-$B$8)),$B$10*EXP(-$B$10*($B$23-$B$20-$B$21-$B$8)))/(1-EXP(-$B$10*($B$23-$B$21-$B$8)))*(1/(1+$B$24)) -> 1.3834248 | K26: =$J26*K$4+K27 -> 0.67451794 | L26: =$V26*$J26 -> 3.0440765e+16 | M26: =$K26/$L$4*$B$18 -> 721.25554 | N26: =IF($I26>$B$23,0,1)*IF($I26<($B$23-$B$21),0,M26) -> 0 | O26: =IF($I26>$B$23,0,1)*IF($I26<($B$23-$B$33),0,1)*IF($I26<($B$23-$B$21),$B$10*EXP(-$B$10*($I26-$B$8)),$B$10*EXP(-$B$10*($B$23-$B$20-$B$21-$B$8)))/(1-EXP(-$B$10*($B$23-$B$21-$B$8)))*(1/(1+$B$24))*($B$18/(SUM($L$7:$L$105)*0.05)) -> 0 | P26: =IF($I26>$B$23,0,1)*IF($I26<($B$23-$B$21),0,1)*$L26 -> 0 | R26: =$I26 -> 0.195 | S26: =IF($I26<$B$23+0.01,$B$10*EXP(-$B$10*($I26-$B$8))/(1-EXP(-$B$10*($B$23-$B$8))),0) -> 1.3834336 | T26: =T27+$S26*0.01 -> 0.67451587 | U26: =T26*$B$18/$W$4 -> 5593.8207 | V26: =10^(1.5*$I26+16.05) -> 2.2003917e+16 | W26: =$S26*$V26*0.01 -> 3.0440959e+14 | Y26: =I26 -> 0.195 | Z26: =IF(AND($Y26<$B$9+$B$27*$B$28,$Y26>$B$9-$B$27*$B$28),NORMDIST($Y26,$B$9,$B$27,0) / (2*NORMDIST($B$28,0,1,1)-1),0) -> 0 | AA26: =$V26*$Z26*$K$4 -> 0 | AB26: =Z26*$K$4+AB27 -> 1.0000236 | AC26: =$AB26*$B$18/$AA$4 -> 0.0074493433
A27: Sigma Mag | B27: 0.2 | D27: ='Out2 for pureChar'!$A27 -> 7.05 | E27: ='Out2 for pureChar'!$B27 -> 0.0014743744 | F27: ='out2 for YC'!$B27 -> 0.0014809869 | I27: =I26+0.01 -> 0.205 | J27: =IF($I27>$B$23,0,1)*IF($I27<($B$23-$B$21),$B$10*EXP(-$B$10*($I27-$B$8)),$B$10*EXP(-$B$10*($B$23-$B$20-$B$21-$B$8)))/(1-EXP(-$B$10*($B$23-$B$21-$B$8)))*(1/(1+$B$24)) -> 1.3550507 | K27: =$J27*K$4+K28 -> 0.66068369 | L27: =$V27*$J27 -> 3.0864238e+16 | M27: =$K27/$L$4*$B$18 -> 706.46271 | N27: =IF($I27>$B$23,0,1)*IF($I27<($B$23-$B$21),0,M27) -> 0 | O27: =IF($I27>$B$23,0,1)*IF($I27<($B$23-$B$33),0,1)*IF($I27<($B$23-$B$21),$B$10*EXP(-$B$10*($I27-$B$8)),$B$10*EXP(-$B$10*($B$23-$B$20-$B$21-$B$8)))/(1-EXP(-$B$10*($B$23-$B$21-$B$8)))*(1/(1+$B$24))*($B$18/(SUM($L$7:$L$105)*0.05)) -> 0 | P27: =IF($I27>$B$23,0,1)*IF($I27<($B$23-$B$21),0,1)*$L27 -> 0 | R27: =$I27 -> 0.205 | S27: =IF($I27<$B$23+0.01,$B$10*EXP(-$B$10*($I27-$B$8))/(1-EXP(-$B$10*($B$23-$B$8))),0) -> 1.3550594 | T27: =T28+$S27*0.01 -> 0.66068153 | U27: =T27*$B$18/$W$4 -> 5479.0913 | V27: =10^(1.5*$I27+16.05) -> 2.2777182e+16 | W27: =$S27*$V27*0.01 -> 3.0864435e+14 | Y27: =I27 -> 0.205 | Z27: =IF(AND($Y27<$B$9+$B$27*$B$28,$Y27>$B$9-$B$27*$B$28),NORMDIST($Y27,$B$9,$B$27,0) / (2*NORMDIST($B$28,0,1,1)-1),0) -> 0 | AA27: =$V27*$Z27*$K$4 -> 0 | AB27: =Z27*$K$4+AB28 -> 1.0000236 | AC27: =$AB27*$B$18/$AA$4 -> 0.0074493433
A28: truncate (n sigma) | B28: 2 | D28: ='Out2 for pureChar'!$A28 -> 7.15 | E28: ='Out2 for pureChar'!$B28 -> 0.0011262031 | F28: ='out2 for YC'!$B28 -> 0.0014809869 | I28: =I27+0.01 -> 0.215 | J28: =IF($I28>$B$23,0,1)*IF($I28<($B$23-$B$21),$B$10*EXP(-$B$10*($I28-$B$8)),$B$10*EXP(-$B$10*($B$23-$B$20-$B$21-$B$8)))/(1-EXP(-$B$10*($B$23-$B$21-$B$8)))*(1/(1+$B$24)) -> 1.3272586 | K28: =$J28*K$4+K29 -> 0.64713318 | L28: =$V28*$J28 -> 3.1293602e+16 | M28: =$K28/$L$4*$B$18 -> 691.97329 | N28: =IF($I28>$B$23,0,1)*IF($I28<($B$23-$B$21),0,M28) -> 0 | O28: =IF($I28>$B$23,0,1)*IF($I28<($B$23-$B$33),0,1)*IF($I28<($B$23-$B$21),$B$10*EXP(-$B$10*($I28-$B$8)),$B$10*EXP(-$B$10*($B$23-$B$20-$B$21-$B$8)))/(1-EXP(-$B$10*($B$23-$B$21-$B$8)))*(1/(1+$B$24))*($B$18/(SUM($L$7:$L$105)*0.05)) -> 0 | P28: =IF($I28>$B$23,0,1)*IF($I28<($B$23-$B$21),0,1)*$L28 -> 0 | R28: =$I28 -> 0.215 | S28: =IF($I28<$B$23+0.01,$B$10*EXP(-$B$10*($I28-$B$8))/(1-EXP(-$B$10*($B$23-$B$8))),0) -> 1.3272671 | T28: =T29+$S28*0.01 -> 0.64713094 | U28: =T28*$B$18/$W$4 -> 5366.715 | V28: =10^(1.5*$I28+16.05) -> 2.3577622e+16 | W28: =$S28*$V28*0.01 -> 3.1293802e+14 | Y28: =I28 -> 0.215 | Z28: =IF(AND($Y28<$B$9+$B$27*$B$28,$Y28>$B$9-$B$27*$B$28),NORMDIST($Y28,$B$9,$B$27,0) / (2*NORMDIST($B$28,0,1,1)-1),0) -> 0 | AA28: =$V28*$Z28*$K$4 -> 0 | AB28: =Z28*$K$4+AB29 -> 1.0000236 | AC28: =$AB28*$B$18/$AA$4 -> 0.0074493433
D29: ='Out2 for pureChar'!$A29 -> 7.25 | E29: ='Out2 for pureChar'!$B29 -> 0.00067337162 | F29: ='out2 for YC'!$B29 -> 0.00059239476 | I29: =I28+0.01 -> 0.225 | J29: =IF($I29>$B$23,0,1)*IF($I29<($B$23-$B$21),$B$10*EXP(-$B$10*($I29-$B$8)),$B$10*EXP(-$B$10*($B$23-$B$20-$B$21-$B$8)))/(1-EXP(-$B$10*($B$23-$B$21-$B$8)))*(1/(1+$B$24)) -> 1.3000365 | K29: =$J29*K$4+K30 -> 0.6338606 | L29: =$V29*$J29 -> 3.1728939e+16 | M29: =$K29/$L$4*$B$18 -> 677.78104 | N29: =IF($I29>$B$23,0,1)*IF($I29<($B$23-$B$21),0,M29) -> 0 | O29: =IF($I29>$B$23,0,1)*IF($I29<($B$23-$B$33),0,1)*IF($I29<($B$23-$B$21),$B$10*EXP(-$B$10*($I29-$B$8)),$B$10*EXP(-$B$10*($B$23-$B$20-$B$21-$B$8)))/(1-EXP(-$B$10*($B$23-$B$21-$B$8)))*(1/(1+$B$24))*($B$18/(SUM($L$7:$L$105)*0.05)) -> 0 | P29: =IF($I29>$B$23,0,1)*IF($I29<($B$23-$B$21),0,1)*$L29 -> 0 | R29: =$I29 -> 0.225 | S29: =IF($I29<$B$23+0.01,$B$10*EXP(-$B$10*($I29-$B$8))/(1-EXP(-$B$10*($B$23-$B$8))),0) -> 1.3000448 | T29: =T30+$S29*0.01 -> 0.63385827 | U29: =T29*$B$18/$W$4 -> 5256.6436 | V29: =10^(1.5*$I29+16.05) -> 2.4406191e+16 | W29: =$S29*$V29*0.01 -> 3.1729142e+14 | Y29: =I29 -> 0.225 | Z29: =IF(AND($Y29<$B$9+$B$27*$B$28,$Y29>$B$9-$B$27*$B$28),NORMDIST($Y29,$B$9,$B$27,0) / (2*NORMDIST($B$28,0,1,1)-1),0) -> 0 | AA29: =$V29*$Z29*$K$4 -> 0 | AB29: =Z29*$K$4+AB30 -> 1.0000236 | AC29: =$AB29*$B$18/$AA$4 -> 0.0074493433
A30: char eqk Rec | B30: =1/(MAX(N7:N901)) -> 135.04508 | D30: ='Out2 for pureChar'!$A30 -> 7.35 | E30: ='Out2 for pureChar'!$B30 -> 0.0002950987 | F30: ='out2 for YC'!$B30 -> 0 | I30: =I29+0.01 -> 0.235 | J30: =IF($I30>$B$23,0,1)*IF($I30<($B$23-$B$21),$B$10*EXP(-$B$10*($I30-$B$8)),$B$10*EXP(-$B$10*($B$23-$B$20-$B$21-$B$8)))/(1-EXP(-$B$10*($B$23-$B$21-$B$8)))*(1/(1+$B$24)) -> 1.2733728 | K30: =$J30*K$4+K31 -> 0.62086023 | L30: =$V30*$J30 -> 3.2170333e+16 | M30: =$K30/$L$4*$B$18 -> 663.87987 | N30: =IF($I30>$B$23,0,1)*IF($I30<($B$23-$B$21),0,M30) -> 0 | O30: =IF($I30>$B$23,0,1)*IF($I30<($B$23-$B$33),0,1)*IF($I30<($B$23-$B$21),$B$10*EXP(-$B$10*($I30-$B$8)),$B$10*EXP(-$B$10*($B$23-$B$20-$B$21-$B$8)))/(1-EXP(-$B$10*($B$23-$B$21-$B$8)))*(1/(1+$B$24))*($B$18/(SUM($L$7:$L$105)*0.05)) -> 0 | P30: =IF($I30>$B$23,0,1)*IF($I30<($B$23-$B$21),0,1)*$L30 -> 0 | R30: =$I30 -> 0.235 | S30: =IF($I30<$B$23+0.01,$B$10*EXP(-$B$10*($I30-$B$8))/(1-EXP(-$B$10*($B$23-$B$8))),0) -> 1.2733809 | T30: =T31+$S30*0.01 -> 0.62085782 | U30: =T30*$B$18/$W$4 -> 5148.8297 | V30: =10^(1.5*$I30+16.05) -> 2.5263877e+16 | W30: =$S30*$V30*0.01 -> 3.2170538e+14 | Y30: =I30 -> 0.235 | Z30: =IF(AND($Y30<$B$9+$B$27*$B$28,$Y30>$B$9-$B$27*$B$28),NORMDIST($Y30,$B$9,$B$27,0) / (2*NORMDIST($B$28,0,1,1)-1),0) -> 0 | AA30: =$V30*$Z30*$K$4 -> 0 | AB30: =Z30*$K$4+AB31 -> 1.0000236 | AC30: =$AB30*$B$18/$AA$4 -> 0.0074493433
A31: moment for density func | B31: =SUM(L7:L1819)*0.01 -> 2.9627125e+21 | D31: ='Out2 for pureChar'!$A31 -> 7.45 | E31: ='Out2 for pureChar'!$B31 -> 0 | F31: ='out2 for YC'!$B31 -> 0 | I31: =I30+0.01 -> 0.245 | J31: =IF($I31>$B$23,0,1)*IF($I31<($B$23-$B$21),$B$10*EXP(-$B$10*($I31-$B$8)),$B$10*EXP(-$B$10*($B$23-$B$20-$B$21-$B$8)))/(1-EXP(-$B$10*($B$23-$B$21-$B$8)))*(1/(1+$B$24)) -> 1.2472559 | K31: =$J31*K$4+K32 -> 0.6081265 | L31: =$V31*$J31 -> 3.2617867e+16 | M31: =$K31/$L$4*$B$18 -> 650.26382 | N31: =IF($I31>$B$23,0,1)*IF($I31<($B$23-$B$21),0,M31) -> 0 | O31: =IF($I31>$B$23,0,1)*IF($I31<($B$23-$B$33),0,1)*IF($I31<($B$23-$B$21),$B$10*EXP(-$B$10*($I31-$B$8)),$B$10*EXP(-$B$10*($B$23-$B$20-$B$21-$B$8)))/(1-EXP(-$B$10*($B$23-$B$21-$B$8)))*(1/(1+$B$24))*($B$18/(SUM($L$7:$L$105)*0.05)) -> 0 | P31: =IF($I31>$B$23,0,1)*IF($I31<($B$23-$B$21),0,1)*$L31 -> 0 | R31: =$I31 -> 0.245 | S31: =IF($I31<$B$23+0.01,$B$10*EXP(-$B$10*($I31-$B$8))/(1-EXP(-$B$10*($B$23-$B$8))),0) -> 1.2472638 | T31: =T32+$S31*0.01 -> 0.60812401 | U31: =T31*$B$18/$W$4 -> 5043.2271 | V31: =10^(1.5*$I31+16.05) -> 2.6151704e+16 | W31: =$S31*$V31*0.01 -> 3.2618075e+14 | Y31: =I31 -> 0.245 | Z31: =IF(AND($Y31<$B$9+$B$27*$B$28,$Y31>$B$9-$B$27*$B$28),NORMDIST($Y31,$B$9,$B$27,0) / (2*NORMDIST($B$28,0,1,1)-1),0) -> 0 | AA31: =$V31*$Z31*$K$4 -> 0 | AB31: =Z31*$K$4+AB32 -> 1.0000236 | AC31: =$AB31*$B$18/$AA$4 -> 0.0074493433
A32: Rec (mu-dm4) | B32: =1/(SUM($O$7:$O$903)*0.05) -> 0.0022449953 | D32: ='Out2 for pureChar'!$A32 -> 7.55 | E32: ='Out2 for pureChar'!$B32 -> 0 | F32: ='out2 for YC'!$B32 -> 0 | I32: =I31+0.01 -> 0.255 | J32: =IF($I32>$B$23,0,1)*IF($I32<($B$23-$B$21),$B$10*EXP(-$B$10*($I32-$B$8)),$B$10*EXP(-$B$10*($B$23-$B$20-$B$21-$B$8)))/(1-EXP(-$B$10*($B$23-$B$21-$B$8)))*(1/(1+$B$24)) -> 1.2216746 | K32: =$J32*K$4+K33 -> 0.59565394 | L32: =$V32*$J32 -> 3.3071627e+16 | M32: =$K32/$L$4*$B$18 -> 636.92703 | N32: =IF($I32>$B$23,0,1)*IF($I32<($B$23-$B$21),0,M32) -> 0 | O32: =IF($I32>$B$23,0,1)*IF($I32<($B$23-$B$33),0,1)*IF($I32<($B$23-$B$21),$B$10*EXP(-$B$10*($I32-$B$8)),$B$10*EXP(-$B$10*($B$23-$B$20-$B$21-$B$8)))/(1-EXP(-$B$10*($B$23-$B$21-$B$8)))*(1/(1+$B$24))*($B$18/(SUM($L$7:$L$105)*0.05)) -> 0 | P32: =IF($I32>$B$23,0,1)*IF($I32<($B$23-$B$21),0,1)*$L32 -> 0 | R32: =$I32 -> 0.255 | S32: =IF($I32<$B$23+0.01,$B$10*EXP(-$B$10*($I32-$B$8))/(1-EXP(-$B$10*($B$23-$B$8))),0) -> 1.2216824 | T32: =T33+$S32*0.01 -> 0.59565137 | U32: =T32*$B$18/$W$4 -> 4939.7903 | V32: =10^(1.5*$I32+16.05) -> 2.7070732e+16 | W32: =$S32*$V32*0.01 -> 3.3071838e+14 | Y32: =I32 -> 0.255 | Z32: =IF(AND($Y32<$B$9+$B$27*$B$28,$Y32>$B$9-$B$27*$B$28),NORMDIST($Y32,$B$9,$B$27,0) / (2*NORMDIST($B$28,0,1,1)-1),0) -> 0 | AA32: =$V32*$Z32*$K$4 -> 0 | AB32: =Z32*$K$4+AB33 -> 1.0000236 | AC32: =$AB32*$B$18/$AA$4 -> 0.0074493433
A33: delta m4 | B33: 0.5 | D33: ='Out2 for pureChar'!$A33 -> 7.65 | E33: ='Out2 for pureChar'!$B33 -> 0 | F33: ='out2 for YC'!$B33 -> 0 | I33: =I32+0.01 -> 0.265 | J33: =IF($I33>$B$23,0,1)*IF($I33<($B$23-$B$21),$B$10*EXP(-$B$10*($I33-$B$8)),$B$10*EXP(-$B$10*($B$23-$B$20-$B$21-$B$8)))/(1-EXP(-$B$10*($B$23-$B$21-$B$8)))*(1/(1+$B$24)) -> 1.1966181 | K33: =$J33*K$4+K34 -> 0.5834372 | L33: =$V33*$J33 -> 3.3531699e+16 | M33: =$K33/$L$4*$B$18 -> 623.86378 | N33: =IF($I33>$B$23,0,1)*IF($I33<($B$23-$B$21),0,M33) -> 0 | O33: =IF($I33>$B$23,0,1)*IF($I33<($B$23-$B$33),0,1)*IF($I33<($B$23-$B$21),$B$10*EXP(-$B$10*($I33-$B$8)),$B$10*EXP(-$B$10*($B$23-$B$20-$B$21-$B$8)))/(1-EXP(-$B$10*($B$23-$B$21-$B$8)))*(1/(1+$B$24))*($B$18/(SUM($L$7:$L$105)*0.05)) -> 0 | P33: =IF($I33>$B$23,0,1)*IF($I33<($B$23-$B$21),0,1)*$L33 -> 0 | R33: =$I33 -> 0.265 | S33: =IF($I33<$B$23+0.01,$B$10*EXP(-$B$10*($I33-$B$8))/(1-EXP(-$B$10*($B$23-$B$8))),0) -> 1.1966257 | T33: =T34+$S33*0.01 -> 0.58343455 | U33: =T33*$B$18/$W$4 -> 4838.4751 | V33: =10^(1.5*$I33+16.05) -> 2.8022056e+16 | W33: =$S33*$V33*0.01 -> 3.3531913e+14 | Y33: =I33 -> 0.265 | Z33: =IF(AND($Y33<$B$9+$B$27*$B$28,$Y33>$B$9-$B$27*$B$28),NORMDIST($Y33,$B$9,$B$27,0) / (2*NORMDIST($B$28,0,1,1)-1),0) -> 0 | AA33: =$V33*$Z33*$K$4 -> 0 | AB33: =Z33*$K$4+AB34 -> 1.0000236 | AC33: =$AB33*$B$18/$AA$4 -> 0.0074493433
D34: ='Out2 for pureChar'!$A34 -> 7.75 | E34: ='Out2 for pureChar'!$B34 -> 0 | F34: ='out2 for YC'!$B34 -> 0 | I34: =I33+0.01 -> 0.275 | J34: =IF($I34>$B$23,0,1)*IF($I34<($B$23-$B$21),$B$10*EXP(-$B$10*($I34-$B$8)),$B$10*EXP(-$B$10*($B$23-$B$20-$B$21-$B$8)))/(1-EXP(-$B$10*($B$23-$B$21-$B$8)))*(1/(1+$B$24)) -> 1.1720754 | K34: =$J34*K$4+K35 -> 0.57147102 | L34: =$V34*$J34 -> 3.3998171e+16 | M34: =$K34/$L$4*$B$18 -> 611.06846 | N34: =IF($I34>$B$23,0,1)*IF($I34<($B$23-$B$21),0,M34) -> 0 | O34: =IF($I34>$B$23,0,1)*IF($I34<($B$23-$B$33),0,1)*IF($I34<($B$23-$B$21),$B$10*EXP(-$B$10*($I34-$B$8)),$B$10*EXP(-$B$10*($B$23-$B$20-$B$21-$B$8)))/(1-EXP(-$B$10*($B$23-$B$21-$B$8)))*(1/(1+$B$24))*($B$18/(SUM($L$7:$L$105)*0.05)) -> 0 | P34: =IF($I34>$B$23,0,1)*IF($I34<($B$23-$B$21),0,1)*$L34 -> 0 | R34: =$I34 -> 0.275 | S34: =IF($I34<$B$23+0.01,$B$10*EXP(-$B$10*($I34-$B$8))/(1-EXP(-$B$10*($B$23-$B$8))),0) -> 1.1720829 | T34: =T35+$S34*0.01 -> 0.57146829 | U34: =T34*$B$18/$W$4 -> 4739.2379 | V34: =10^(1.5*$I34+16.05) -> 2.9006812e+16 | W34: =$S34*$V34*0.01 -> 3.3998388e+14 | Y34: =I34 -> 0.275 | Z34: =IF(AND($Y34<$B$9+$B$27*$B$28,$Y34>$B$9-$B$27*$B$28),NORMDIST($Y34,$B$9,$B$27,0) / (2*NORMDIST($B$28,0,1,1)-1),0) -> 0 | AA34: =$V34*$Z34*$K$4 -> 0 | AB34: =Z34*$K$4+AB35 -> 1.0000236 | AC34: =$AB34*$B$18/$AA$4 -> 0.0074493433
B35: =B18/B31 -> 1069.2904 | D35: ='Out2 for pureChar'!$A35 -> 7.85 | E35: ='Out2 for pureChar'!$B35 -> 0 | F35: ='out2 for YC'!$B35 -> 0 | I35: =I34+0.01 -> 0.285 | J35: =IF($I35>$B$23,0,1)*IF($I35<($B$23-$B$21),$B$10*EXP(-$B$10*($I35-$B$8)),$B$10*EXP(-$B$10*($B$23-$B$20-$B$21-$B$8)))/(1-EXP(-$B$10*($B$23-$B$21-$B$8)))*(1/(1+$B$24)) -> 1.1480361 | K35: =$J35*K$4+K36 -> 0.55975026 | L35: =$V35*$J35 -> 3.4471133e+16 | M35: =$K35/$L$4*$B$18 -> 598.53557 | N35: =IF($I35>$B$23,0,1)*IF($I35<($B$23-$B$21),0,M35) -> 0 | O35: =IF($I35>$B$23,0,1)*IF($I35<($B$23-$B$33),0,1)*IF($I35<($B$23-$B$21),$B$10*EXP(-$B$10*($I35-$B$8)),$B$10*EXP(-$B$10*($B$23-$B$20-$B$21-$B$8)))/(1-EXP(-$B$10*($B$23-$B$21-$B$8)))*(1/(1+$B$24))*($B$18/(SUM($L$7:$L$105)*0.05)) -> 0 | P35: =IF($I35>$B$23,0,1)*IF($I35<($B$23-$B$21),0,1)*$L35 -> 0 | R35: =$I35 -> 0.285 | S35: =IF($I35<$B$23+0.01,$B$10*EXP(-$B$10*($I35-$B$8))/(1-EXP(-$B$10*($B$23-$B$8))),0) -> 1.1480435 | T35: =T36+$S35*0.01 -> 0.55974746 | U35: =T35*$B$18/$W$4 -> 4642.036 | V35: =10^(1.5*$I35+16.05) -> 3.0026174e+16 | W35: =$S35*$V35*0.01 -> 3.4471353e+14 | Y35: =I35 -> 0.285 | Z35: =IF(AND($Y35<$B$9+$B$27*$B$28,$Y35>$B$9-$B$27*$B$28),NORMDIST($Y35,$B$9,$B$27,0) / (2*NORMDIST($B$28,0,1,1)-1),0) -> 0 | AA35: =$V35*$Z35*$K$4 -> 0 | AB35: =Z35*$K$4+AB36 -> 1.0000236 | AC35: =$AB35*$B$18/$AA$4 -> 0.0074493433
D36: ='Out2 for pureChar'!$A36 -> 7.95 | E36: ='Out2 for pureChar'!$B36 -> 0 | F36: ='out2 for YC'!$B36 -> 0 | I36: =I35+0.01 -> 0.295 | J36: =IF($I36>$B$23,0,1)*IF($I36<($B$23-$B$21),$B$10*EXP(-$B$10*($I36-$B$8)),$B$10*EXP(-$B$10*($B$23-$B$20-$B$21-$B$8)))/(1-EXP(-$B$10*($B$23-$B$21-$B$8)))*(1/(1+$B$24)) -> 1.1244899 | K36: =$J36*K$4+K37 -> 0.5482699 | L36: =$V36*$J36 -> 3.4950674e+16 | M36: =$K36/$L$4*$B$18 -> 586.25973 | N36: =IF($I36>$B$23,0,1)*IF($I36<($B$23-$B$21),0,M36) -> 0 | O36: =IF($I36>$B$23,0,1)*IF($I36<($B$23-$B$33),0,1)*IF($I36<($B$23-$B$21),$B$10*EXP(-$B$10*($I36-$B$8)),$B$10*EXP(-$B$10*($B$23-$B$20-$B$21-$B$8)))/(1-EXP(-$B$10*($B$23-$B$21-$B$8)))*(1/(1+$B$24))*($B$18/(SUM($L$7:$L$105)*0.05)) -> 0 | P36: =IF($I36>$B$23,0,1)*IF($I36<($B$23-$B$21),0,1)*$L36 -> 0 | R36: =$I36 -> 0.295 | S36: =IF($I36<$B$23+0.01,$B$10*EXP(-$B$10*($I36-$B$8))/(1-EXP(-$B$10*($B$23-$B$8))),0) -> 1.1244971 | T36: =T37+$S36*0.01 -> 0.54826703 | U36: =T36*$B$18/$W$4 -> 4546.8277 | V36: =10^(1.5*$I36+16.05) -> 3.1081359e+16 | W36: =$S36*$V36*0.01 -> 3.4950897e+14 | Y36: =I36 -> 0.295 | Z36: =IF(AND($Y36<$B$9+$B$27*$B$28,$Y36>$B$9-$B$27*$B$28),NORMDIST($Y36,$B$9,$B$27,0) / (2*NORMDIST($B$28,0,1,1)-1),0) -> 0 | AA36: =$V36*$Z36*$K$4 -> 0 | AB36: =Z36*$K$4+AB37 -> 1.0000236 | AC36: =$AB36*$B$18/$AA$4 -> 0.0074493433
D37: ='Out2 for pureChar'!$A37 -> 8.05 | E37: ='Out2 for pureChar'!$B37 -> 0 | F37: ='out2 for YC'!$B37 -> 0 | I37: =I36+0.01 -> 0.305 | J37: =IF($I37>$B$23,0,1)*IF($I37<($B$23-$B$21),$B$10*EXP(-$B$10*($I37-$B$8)),$B$10*EXP(-$B$10*($B$23-$B$20-$B$21-$B$8)))/(1-EXP(-$B$10*($B$23-$B$21-$B$8)))*(1/(1+$B$24)) -> 1.1014266 | K37: =$J37*K$4+K38 -> 0.537025 | L37: =$V37*$J37 -> 3.5436886e+16 | M37: =$K37/$L$4*$B$18 -> 574.23567 | N37: =IF($I37>$B$23,0,1)*IF($I37<($B$23-$B$21),0,M37) -> 0 | O37: =IF($I37>$B$23,0,1)*IF($I37<($B$23-$B$33),0,1)*IF($I37<($B$23-$B$21),$B$10*EXP(-$B$10*($I37-$B$8)),$B$10*EXP(-$B$10*($B$23-$B$20-$B$21-$B$8)))/(1-EXP(-$B$10*($B$23-$B$21-$B$8)))*(1/(1+$B$24))*($B$18/(SUM($L$7:$L$105)*0.05)) -> 0 | P37: =IF($I37>$B$23,0,1)*IF($I37<($B$23-$B$21),0,1)*$L37 -> 0 | R37: =$I37 -> 0.305 | S37: =IF($I37<$B$23+0.01,$B$10*EXP(-$B$10*($I37-$B$8))/(1-EXP(-$B$10*($B$23-$B$8))),0) -> 1.1014336 | T37: =T38+$S37*0.01 -> 0.53702205 | U37: =T37*$B$18/$W$4 -> 4453.5722 | V37: =10^(1.5*$I37+16.05) -> 3.2173625e+16 | W37: =$S37*$V37*0.01 -> 3.5437113e+14 | Y37: =I37 -> 0.305 | Z37: =IF(AND($Y37<$B$9+$B$27*$B$28,$Y37>$B$9-$B$27*$B$28),NORMDIST($Y37,$B$9,$B$27,0) / (2*NORMDIST($B$28,0,1,1)-1),0) -> 0 | AA37: =$V37*$Z37*$K$4 -> 0 | AB37: =Z37*$K$4+AB38 -> 1.0000236 | AC37: =$AB37*$B$18/$AA$4 -> 0.0074493433
A38: Exp | B38: =SUM(L7:L106)*0.02 -> 1.0034312e+17 | D38: ='Out2 for pureChar'!$A38 -> 8.15 | E38: ='Out2 for pureChar'!$B38 -> 0 | F38: ='out2 for YC'!$B38 -> 0 | I38: =I37+0.01 -> 0.315 | J38: =IF($I38>$B$23,0,1)*IF($I38<($B$23-$B$21),$B$10*EXP(-$B$10*($I38-$B$8)),$B$10*EXP(-$B$10*($B$23-$B$20-$B$21-$B$8)))/(1-EXP(-$B$10*($B$23-$B$21-$B$8)))*(1/(1+$B$24)) -> 1.0788363 | K38: =$J38*K$4+K39 -> 0.52601074 | L38: =$V38*$J38 -> 3.5929863e+16 | M38: =$K38/$L$4*$B$18 -> 562.45822 | N38: =IF($I38>$B$23,0,1)*IF($I38<($B$23-$B$21),0,M38) -> 0 | O38: =IF($I38>$B$23,0,1)*IF($I38<($B$23-$B$33),0,1)*IF($I38<($B$23-$B$21),$B$10*EXP(-$B$10*($I38-$B$8)),$B$10*EXP(-$B$10*($B$23-$B$20-$B$21-$B$8)))/(1-EXP(-$B$10*($B$23-$B$21-$B$8)))*(1/(1+$B$24))*($B$18/(SUM($L$7:$L$105)*0.05)) -> 0 | P38: =IF($I38>$B$23,0,1)*IF($I38<($B$23-$B$21),0,1)*$L38 -> 0 | R38: =$I38 -> 0.315 | S38: =IF($I38<$B$23+0.01,$B$10*EXP(-$B$10*($I38-$B$8))/(1-EXP(-$B$10*($B$23-$B$8))),0) -> 1.0788432 | T38: =T39+$S38*0.01 -> 0.52600772 | U38: =T38*$B$18/$W$4 -> 4362.2293 | V38: =10^(1.5*$I38+16.05) -> 3.3304276e+16 | W38: =$S38*$V38*0.01 -> 3.5930092e+14 | Y38: =I38 -> 0.315 | Z38: =IF(AND($Y38<$B$9+$B$27*$B$28,$Y38>$B$9-$B$27*$B$28),NORMDIST($Y38,$B$9,$B$27,0) / (2*NORMDIST($B$28,0,1,1)-1),0) -> 0 | AA38: =$V38*$Z38*$K$4 -> 0 | AB38: =Z38*$K$4+AB39 -> 1.0000236 | AC38: =$AB38*$B$18/$AA$4 -> 0.0074493433
A39: Char | B39: =B31-B38 -> 2.9626122e+21 | D39: ='Out2 for pureChar'!$A39 -> 8.25 | E39: ='Out2 for pureChar'!$B39 -> 0 | F39: ='out2 for YC'!$B39 -> 0 | I39: =I38+0.01 -> 0.325 | J39: =IF($I39>$B$23,0,1)*IF($I39<($B$23-$B$21),$B$10*EXP(-$B$10*($I39-$B$8)),$B$10*EXP(-$B$10*($B$23-$B$20-$B$21-$B$8)))/(1-EXP(-$B$10*($B$23-$B$21-$B$8)))*(1/(1+$B$24)) -> 1.0567094 | K39: =$J39*K$4+K40 -> 0.51522237 | L39: =$V39*$J39 -> 3.6429697e+16 | M39: =$K39/$L$4*$B$18 -> 550.92233 | N39: =IF($I39>$B$23,0,1)*IF($I39<($B$23-$B$21),0,M39) -> 0 | O39: =IF($I39>$B$23,0,1)*IF($I39<($B$23-$B$33),0,1)*IF($I39<($B$23-$B$21),$B$10*EXP(-$B$10*($I39-$B$8)),$B$10*EXP(-$B$10*($B$23-$B$20-$B$21-$B$8)))/(1-EXP(-$B$10*($B$23-$B$21-$B$8)))*(1/(1+$B$24))*($B$18/(SUM($L$7:$L$105)*0.05)) -> 0 | P39: =IF($I39>$B$23,0,1)*IF($I39<($B$23-$B$21),0,1)*$L39 -> 0 | R39: =$I39 -> 0.325 | S39: =IF($I39<$B$23+0.01,$B$10*EXP(-$B$10*($I39-$B$8))/(1-EXP(-$B$10*($B$23-$B$8))),0) -> 1.0567161 | T39: =T40+$S39*0.01 -> 0.51521929 | U39: =T39*$B$18/$W$4 -> 4272.7598 | V39: =10^(1.5*$I39+16.05) -> 3.4474661e+16 | W39: =$S39*$V39*0.01 -> 3.6429929e+14 | Y39: =I39 -> 0.325 | Z39: =IF(AND($Y39<$B$9+$B$27*$B$28,$Y39>$B$9-$B$27*$B$28),NORMDIST($Y39,$B$9,$B$27,0) / (2*NORMDIST($B$28,0,1,1)-1),0) -> 0 | AA39: =$V39*$Z39*$K$4 -> 0 | AB39: =Z39*$K$4+AB40 -> 1.0000236 | AC39: =$AB39*$B$18/$AA$4 -> 0.0074493433
D40: ='Out2 for pureChar'!$A40 -> 8.35 | E40: ='Out2 for pureChar'!$B40 -> 0 | F40: ='out2 for YC'!$B40 -> 0 | I40: =I39+0.01 -> 0.335 | J40: =IF($I40>$B$23,0,1)*IF($I40<($B$23-$B$21),$B$10*EXP(-$B$10*($I40-$B$8)),$B$10*EXP(-$B$10*($B$23-$B$20-$B$21-$B$8)))/(1-EXP(-$B$10*($B$23-$B$21-$B$8)))*(1/(1+$B$24)) -> 1.0350362 | K40: =$J40*K$4+K41 -> 0.50465528 | L40: =$V40*$J40 -> 3.6936484e+16 | M40: =$K40/$L$4*$B$18 -> 539.62304 | N40: =IF($I40>$B$23,0,1)*IF($I40<($B$23-$B$21),0,M40) -> 0 | O40: =IF($I40>$B$23,0,1)*IF($I40<($B$23-$B$33),0,1)*IF($I40<($B$23-$B$21),$B$10*EXP(-$B$10*($I40-$B$8)),$B$10*EXP(-$B$10*($B$23-$B$20-$B$21-$B$8)))/(1-EXP(-$B$10*($B$23-$B$21-$B$8)))*(1/(1+$B$24))*($B$18/(SUM($L$7:$L$105)*0.05)) -> 0 | P40: =IF($I40>$B$23,0,1)*IF($I40<($B$23-$B$21),0,1)*$L40 -> 0 | R40: =$I40 -> 0.335 | S40: =IF($I40<$B$23+0.01,$B$10*EXP(-$B$10*($I40-$B$8))/(1-EXP(-$B$10*($B$23-$B$8))),0) -> 1.0350428 | T40: =T41+$S40*0.01 -> 0.50465213 | U40: =T40*$B$18/$W$4 -> 4185.1254 | V40: =10^(1.5*$I40+16.05) -> 3.5686175e+16 | W40: =$S40*$V40*0.01 -> 3.693672e+14 | Y40: =I40 -> 0.335 | Z40: =IF(AND($Y40<$B$9+$B$27*$B$28,$Y40>$B$9-$B$27*$B$28),NORMDIST($Y40,$B$9,$B$27,0) / (2*NORMDIST($B$28,0,1,1)-1),0) -> 0 | AA40: =$V40*$Z40*$K$4 -> 0 | AB40: =Z40*$K$4+AB41 -> 1.0000236 | AC40: =$AB40*$B$18/$AA$4 -> 0.0074493433
A41: fraction moment Char | B41: =$P$4/$L$4 -> 0.93626809 | D41: ='Out2 for pureChar'!$A41 -> 8.45 | E41: ='Out2 for pureChar'!$B41 -> 0 | F41: ='out2 for YC'!$B41 -> 0 | I41: =I40+0.01 -> 0.345 | J41: =IF($I41>$B$23,0,1)*IF($I41<($B$23-$B$21),$B$10*EXP(-$B$10*($I41-$B$8)),$B$10*EXP(-$B$10*($B$23-$B$20-$B$21-$B$8)))/(1-EXP(-$B$10*($B$23-$B$21-$B$8)))*(1/(1+$B$24)) -> 1.0138076 | K41: =$J41*K$4+K42 -> 0.49430492 | L41: =$V41*$J41 -> 3.7450322e+16 | M41: =$K41/$L$4*$B$18 -> 528.55549 | N41: =IF($I41>$B$23,0,1)*IF($I41<($B$23-$B$21),0,M41) -> 0 | O41: =IF($I41>$B$23,0,1)*IF($I41<($B$23-$B$33),0,1)*IF($I41<($B$23-$B$21),$B$10*EXP(-$B$10*($I41-$B$8)),$B$10*EXP(-$B$10*($B$23-$B$20-$B$21-$B$8)))/(1-EXP(-$B$10*($B$23-$B$21-$B$8)))*(1/(1+$B$24))*($B$18/(SUM($L$7:$L$105)*0.05)) -> 0 | P41: =IF($I41>$B$23,0,1)*IF($I41<($B$23-$B$21),0,1)*$L41 -> 0 | R41: =$I41 -> 0.345 | S41: =IF($I41<$B$23+0.01,$B$10*EXP(-$B$10*($I41-$B$8))/(1-EXP(-$B$10*($B$23-$B$8))),0) -> 1.0138141 | T41: =T42+$S41*0.01 -> 0.4943017 | U41: =T41*$B$18/$W$4 -> 4099.2884 | V41: =10^(1.5*$I41+16.05) -> 3.6940264e+16 | W41: =$S41*$V41*0.01 -> 3.7450561e+14 | Y41: =I41 -> 0.345 | Z41: =IF(AND($Y41<$B$9+$B$27*$B$28,$Y41>$B$9-$B$27*$B$28),NORMDIST($Y41,$B$9,$B$27,0) / (2*NORMDIST($B$28,0,1,1)-1),0) -> 0 | AA41: =$V41*$Z41*$K$4 -> 0 | AB41: =Z41*$K$4+AB42 -> 1.0000236 | AC41: =$AB41*$B$18/$AA$4 -> 0.0074493433
D42: ='Out2 for pureChar'!$A42 -> 8.55 | E42: ='Out2 for pureChar'!$B42 -> 0 | F42: ='out2 for YC'!$B42 -> 0 | I42: =I41+0.01 -> 0.355 | J42: =IF($I42>$B$23,0,1)*IF($I42<($B$23-$B$21),$B$10*EXP(-$B$10*($I42-$B$8)),$B$10*EXP(-$B$10*($B$23-$B$20-$B$21-$B$8)))/(1-EXP(-$B$10*($B$23-$B$21-$B$8)))*(1/(1+$B$24)) -> 0.99301442 | K42: =$J42*K$4+K43 -> 0.48416684 | L42: =$V42*$J42 -> 3.7971308e+16 | M42: =$K42/$L$4*$B$18 -> 517.71495 | N42: =IF($I42>$B$23,0,1)*IF($I42<($B$23-$B$21),0,M42) -> 0 | O42: =IF($I42>$B$23,0,1)*IF($I42<($B$23-$B$33),0,1)*IF($I42<($B$23-$B$21),$B$10*EXP(-$B$10*($I42-$B$8)),$B$10*EXP(-$B$10*($B$23-$B$20-$B$21-$B$8)))/(1-EXP(-$B$10*($B$23-$B$21-$B$8)))*(1/(1+$B$24))*($B$18/(SUM($L$7:$L$105)*0.05)) -> 0 | P42: =IF($I42>$B$23,0,1)*IF($I42<($B$23-$B$21),0,1)*$L42 -> 0 | R42: =$I42 -> 0.355 | S42: =IF($I42<$B$23+0.01,$B$10*EXP(-$B$10*($I42-$B$8))/(1-EXP(-$B$10*($B$23-$B$8))),0) -> 0.99302076 | T42: =T43+$S42*0.01 -> 0.48416356 | U42: =T42*$B$18/$W$4 -> 4015.2119 | V42: =10^(1.5*$I42+16.05) -> 3.8238425e+16 | W42: =$S42*$V42*0.01 -> 3.797155e+14 | Y42: =I42 -> 0.355 | Z42: =IF(AND($Y42<$B$9+$B$27*$B$28,$Y42>$B$9-$B$27*$B$28),NORMDIST($Y42,$B$9,$B$27,0) / (2*NORMDIST($B$28,0,1,1)-1),0) -> 0 | AA42: =$V42*$Z42*$K$4 -> 0 | AB42: =Z42*$K$4+AB43 -> 1.0000236 | AC42: =$AB42*$B$18/$AA$4 -> 0.0074493433
...

Sheet Out2 for pureChar
I1: =SUM(I5:AR5) -> 1
B2: sum | C2: sum
B3: =SUM(B7:B43) -> 0.0074493433 | C3: =SUM(C7:C43) -> 1 | I3: 4.999 | J3: 5.1 | K3: =J3+0.1 -> 5.2 | L3: =K3+0.1 -> 5.3 | M3: =L3+0.1 -> 5.4 | N3: =M3+0.1 -> 5.5 | O3: =N3+0.1 -> 5.6 | P3: =O3+0.1 -> 5.7 | Q3: =P3+0.1 -> 5.8 | R3: =Q3+0.1 -> 5.9 | ... AR3: =AQ3+0.1 -> 8.5
I4: 5.1 | J4: =J3+0.1 -> 5.2 | K4: =K3+0.1 -> 5.3 | L4: =L3+0.1 -> 5.4 | M4: =M3+0.1 -> 5.5 | N4: =N3+0.1 -> 5.6 | O4: =O3+0.1 -> 5.7 | P4: =P3+0.1 -> 5.8 | Q4: =Q3+0.1 -> 5.9 | ... AR4: =AR3+0.1 -> 8.6
H5: =SUM(H7:H863) -> 0.0074493433 | I5: =SUM(I7:I863)/$H$5 -> 0 | J5: =SUM(J7:J863)/$H$5 -> 0 | K5: =SUM(K7:K863)/$H$5 -> 0 | L5: =SUM(L7:L863)/$H$5 -> 0 | M5: =SUM(M7:M863)/$H$5 -> 0 | N5: =SUM(N7:N863)/$H$5 -> 0 | O5: =SUM(O7:O863)/$H$5 -> 0 | P5: =SUM(P7:P863)/$H$5 -> 0 | ... AR5: =SUM(AR7:AR863)/$H$5 -> 0
A6: Mag | B6: rate of mag | C6: P(M) | D6: column | E6: N(M) for YC85 | G6: mag
A7: 5.05 | B7: =$C7*$H$5 -> 0 | C7: {=INDIRECT(ADDRESS(5,$D7,1,FALSE),FALSE)} -> 0 | D7: 9 | E7: =moment_rate!$AC7 -> 0.0074493433 | F7: =E7-E8 -> 0 | G7: =moment_rate!I7-0.005 -> 0 | H7: =IF($G7>=4.999,(E7-E8),0) -> 0 | I7: =IF(AND($G7>=I$3,$G7<I$4),$F7,0) -> 0 | J7: =IF(AND($G7>=J$3,$G7<J$4),$F7,0) -> 0 | K7: =IF(AND($G7>=K$3,$G7<K$4),$F7,0) -> 0 | L7: =IF(AND($G7>=L$3,$G7<L$4),$F7,0) -> 0 | M7: =IF(AND($G7>=M$3,$G7<M$4),$F7,0) -> 0 | N7: =IF(AND($G7>=N$3,$G7<N$4),$F7,0) -> 0 | O7: =IF(AND($G7>=O$3,$G7<O$4),$F7,0) -> 0 | P7: =IF(AND($G7>=P$3,$G7<P$4),$F7,0) -> 0 | ... AR7: =IF(AND($G7>=AR$3,$G7<AR$4),$F7,0) -> 0
A8: =A7+0.1 -> 5.15 | B8: =$C8*$H$5 -> 0 | C8: {=INDIRECT(ADDRESS(5,$D8,1,FALSE),FALSE)} -> 0 | D8: =D7+1 -> 10 | E8: =moment_rate!$AC8 -> 0.0074493433 | F8: =E8-E9 -> 0 | G8: =moment_rate!I8-0.005 -> 0.01 | H8: =IF($G8>=4.999,(E8-E9),0) -> 0 | I8: =IF(AND($G8>=I$3,$G8<I$4),$F8,0) -> 0 | J8: =IF(AND($G8>=J$3,$G8<J$4),$F8,0) -> 0 | K8: =IF(AND($G8>=K$3,$G8<K$4),$F8,0) -> 0 | L8: =IF(AND($G8>=L$3,$G8<L$4),$F8,0) -> 0 | M8: =IF(AND($G8>=M$3,$G8<M$4),$F8,0) -> 0 | N8: =IF(AND($G8>=N$3,$G8<N$4),$F8,0) -> 0 | O8: =IF(AND($G8>=O$3,$G8<O$4),$F8,0) -> 0 | P8: =IF(AND($G8>=P$3,$G8<P$4),$F8,0) -> 0 | ... AR8: =IF(AND($G8>=AR$3,$G8<AR$4),$F8,0) -> 0
A9: =A8+0.1 -> 5.25 | B9: =$C9*$H$5 -> 0 | C9: {=INDIRECT(ADDRESS(5,$D9,1,FALSE),FALSE)} -> 0 | D9: =D8+1 -> 11 | E9: =moment_rate!$AC9 -> 0.0074493433 | F9: =E9-E10 -> 0 | G9: =moment_rate!I9-0.005 -> 0.02 | H9: =IF($G9>=4.999,(E9-E10),0) -> 0 | I9: =IF(AND($G9>=I$3,$G9<I$4),$F9,0) -> 0 | J9: =IF(AND($G9>=J$3,$G9<J$4),$F9,0) -> 0 | K9: =IF(AND($G9>=K$3,$G9<K$4),$F9,0) -> 0 | L9: =IF(AND($G9>=L$3,$G9<L$4),$F9,0) -> 0 | M9: =IF(AND($G9>=M$3,$G9<M$4),$F9,0) -> 0 | N9: =IF(AND($G9>=N$3,$G9<N$4),$F9,0) -> 0 | O9: =IF(AND($G9>=O$3,$G9<O$4),$F9,0) -> 0 | P9: =IF(AND($G9>=P$3,$G9<P$4),$F9,0) -> 0 | ... AR9: =IF(AND($G9>=AR$3,$G9<AR$4),$F9,0) -> 0
A10: =A9+0.1 -> 5.35 | B10: =$C10*$H$5 -> 0 | C10: {=INDIRECT(ADDRESS(5,$D10,1,FALSE),FALSE)} -> 0 | D10: =D9+1 -> 12 | E10: =moment_rate!$AC10 -> 0.0074493433 | F10: =E10-E11 -> 0 | G10: =moment_rate!I10-0.005 -> 0.03 | H10: =IF($G10>=4.999,(E10-E11),0) -> 0 | I10: =IF(AND($G10>=I$3,$G10<I$4),$F10,0) -> 0 | J10: =IF(AND($G10>=J$3,$G10<J$4),$F10,0) -> 0 | K10: =IF(AND($G10>=K$3,$G10<K$4),$F10,0) -> 0 | L10: =IF(AND($G10>=L$3,$G10<L$4),$F10,0) -> 0 | M10: =IF(AND($G10>=M$3,$G10<M$4),$F10,0) -> 0 | N10: =IF(AND($G10>=N$3,$G10<N$4),$F10,0) -> 0 | O10: =IF(AND($G10>=O$3,$G10<O$4),$F10,0) -> 0 | P10: =IF(AND($G10>=P$3,$G10<P$4),$F10,0) -> 0 | ... AR10: =IF(AND($G10>=AR$3,$G10<AR$4),$F10,0) -> 0
A11: =A10+0.1 -> 5.45 | B11: =$C11*$H$5 -> 0 | C11: {=INDIRECT(ADDRESS(5,$D11,1,FALSE),FALSE)} -> 0 | D11: =D10+1 -> 13 | E11: =moment_rate!$AC11 -> 0.0074493433 | F11: =E11-E12 -> 0 | G11: =moment_rate!I11-0.005 -> 0.04 | H11: =IF($G11>=4.999,(E11-E12),0) -> 0 | I11: =IF(AND($G11>=I$3,$G11<I$4),$F11,0) -> 0 | J11: =IF(AND($G11>=J$3,$G11<J$4),$F11,0) -> 0 | K11: =IF(AND($G11>=K$3,$G11<K$4),$F11,0) -> 0 | L11: =IF(AND($G11>=L$3,$G11<L$4),$F11,0) -> 0 | M11: =IF(AND($G11>=M$3,$G11<M$4),$F11,0) -> 0 | N11: =IF(AND($G11>=N$3,$G11<N$4),$F11,0) -> 0 | O11: =IF(AND($G11>=O$3,$G11<O$4),$F11,0) -> 0 | P11: =IF(AND($G11>=P$3,$G11<P$4),$F11,0) -> 0 | ... AR11: =IF(AND($G11>=AR$3,$G11<AR$4),$F11,0) -> 0
A12: =A11+0.1 -> 5.55 | B12: =$C12*$H$5 -> 0 | C12: {=INDIRECT(ADDRESS(5,$D12,1,FALSE),FALSE)} -> 0 | D12: =D11+1 -> 14 | E12: =moment_rate!$AC12 -> 0.0074493433 | F12: =E12-E13 -> 0 | G12: =moment_rate!I12-0.005 -> 0.05 | H12: =IF($G12>=4.999,(E12-E13),0) -> 0 | I12: =IF(AND($G12>=I$3,$G12<I$4),$F12,0) -> 0 | J12: =IF(AND($G12>=J$3,$G12<J$4),$F12,0) -> 0 | K12: =IF(AND($G12>=K$3,$G12<K$4),$F12,0) -> 0 | L12: =IF(AND($G12>=L$3,$G12<L$4),$F12,0) -> 0 | M12: =IF(AND($G12>=M$3,$G12<M$4),$F12,0) -> 0 | N12: =IF(AND($G12>=N$3,$G12<N$4),$F12,0) -> 0 | O12: =IF(AND($G12>=O$3,$G12<O$4),$F12,0) -> 0 | P12: =IF(AND($G12>=P$3,$G12<P$4),$F12,0) -> 0 | ... AR12: =IF(AND($G12>=AR$3,$G12<AR$4),$F12,0) -> 0
A13: =A12+0.1 -> 5.65 | B13: =$C13*$H$5 -> 0 | C13: {=INDIRECT(ADDRESS(5,$D13,1,FALSE),FALSE)} -> 0 | D13: =D12+1 -> 15 | E13: =moment_rate!$AC13 -> 0.0074493433 | F13: =E13-E14 -> 0 | G13: =moment_rate!I13-0.005 -> 0.06 | H13: =IF($G13>=4.999,(E13-E14),0) -> 0 | I13: =IF(AND($G13>=I$3,$G13<I$4),$F13,0) -> 0 | J13: =IF(AND($G13>=J$3,$G13<J$4),$F13,0) -> 0 | K13: =IF(AND($G13>=K$3,$G13<K$4),$F13,0) -> 0 | L13: =IF(AND($G13>=L$3,$G13<L$4),$F13,0) -> 0 | M13: =IF(AND($G13>=M$3,$G13<M$4),$F13,0) -> 0 | N13: =IF(AND($G13>=N$3,$G13<N$4),$F13,0) -> 0 | O13: =IF(AND($G13>=O$3,$G13<O$4),$F13,0) -> 0 | P13: =IF(AND($G13>=P$3,$G13<P$4),$F13,0) -> 0 | ... AR13: =IF(AND($G13>=AR$3,$G13<AR$4),$F13,0) -> 0
A14: =A13+0.1 -> 5.75 | B14: =$C14*$H$5 -> 0 | C14: {=INDIRECT(ADDRESS(5,$D14,1,FALSE),FALSE)} -> 0 | D14: =D13+1 -> 16 | E14: =moment_rate!$AC14 -> 0.0074493433 | F14: =E14-E15 -> 0 | G14: =moment_rate!I14-0.005 -> 0.07 | H14: =IF($G14>=4.999,(E14-E15),0) -> 0 | I14: =IF(AND($G14>=I$3,$G14<I$4),$F14,0) -> 0 | J14: =IF(AND($G14>=J$3,$G14<J$4),$F14,0) -> 0 | K14: =IF(AND($G14>=K$3,$G14<K$4),$F14,0) -> 0 | L14: =IF(AND($G14>=L$3,$G14<L$4),$F14,0) -> 0 | M14: =IF(AND($G14>=M$3,$G14<M$4),$F14,0) -> 0 | N14: =IF(AND($G14>=N$3,$G14<N$4),$F14,0) -> 0 | O14: =IF(AND($G14>=O$3,$G14<O$4),$F14,0) -> 0 | P14: =IF(AND($G14>=P$3,$G14<P$4),$F14,0) -> 0 | ... AR14: =IF(AND($G14>=AR$3,$G14<AR$4),$F14,0) -> 0
A15: =A14+0.1 -> 5.85 | B15: =$C15*$H$5 -> 0 | C15: {=INDIRECT(ADDRESS(5,$D15,1,FALSE),FALSE)} -> 0 | D15: =D14+1 -> 17 | E15: =moment_rate!$AC15 -> 0.0074493433 | F15: =E15-E16 -> 0 | G15: =moment_rate!I15-0.005 -> 0.08 | H15: =IF($G15>=4.999,(E15-E16),0) -> 0 | I15: =IF(AND($G15>=I$3,$G15<I$4),$F15,0) -> 0 | J15: =IF(AND($G15>=J$3,$G15<J$4),$F15,0) -> 0 | K15: =IF(AND($G15>=K$3,$G15<K$4),$F15,0) -> 0 | L15: =IF(AND($G15>=L$3,$G15<L$4),$F15,0) -> 0 | M15: =IF(AND($G15>=M$3,$G15<M$4),$F15,0) -> 0 | N15: =IF(AND($G15>=N$3,$G15<N$4),$F15,0) -> 0 | O15: =IF(AND($G15>=O$3,$G15<O$4),$F15,0) -> 0 | P15: =IF(AND($G15>=P$3,$G15<P$4),$F15,0) -> 0 | ... AR15: =IF(AND($G15>=AR$3,$G15<AR$4),$F15,0) -> 0
A16: =A15+0.1 -> 5.95 | B16: =$C16*$H$5 -> 0 | C16: {=INDIRECT(ADDRESS(5,$D16,1,FALSE),FALSE)} -> 0 | D16: =D15+1 -> 18 | E16: =moment_rate!$AC16 -> 0.0074493433 | F16: =E16-E17 -> 0 | G16: =moment_rate!I16-0.005 -> 0.09 | H16: =IF($G16>=4.999,(E16-E17),0) -> 0 | I16: =IF(AND($G16>=I$3,$G16<I$4),$F16,0) -> 0 | J16: =IF(AND($G16>=J$3,$G16<J$4),$F16,0) -> 0 | K16: =IF(AND($G16>=K$3,$G16<K$4),$F16,0) -> 0 | L16: =IF(AND($G16>=L$3,$G16<L$4),$F16,0) -> 0 | M16: =IF(AND($G16>=M$3,$G16<M$4),$F16,0) -> 0 | N16: =IF(AND($G16>=N$3,$G16<N$4),$F16,0) -> 0 | O16: =IF(AND($G16>=O$3,$G16<O$4),$F16,0) -> 0 | P16: =IF(AND($G16>=P$3,$G16<P$4),$F16,0) -> 0 | ... AR16: =IF(AND($G16>=AR$3,$G16<AR$4),$F16,0) -> 0
A17: =A16+0.1 -> 6.05 | B17: =$C17*$H$5 -> 0 | C17: {=INDIRECT(ADDRESS(5,$D17,1,FALSE),FALSE)} -> 0 | D17: =D16+1 -> 19 | E17: =moment_rate!$AC17 -> 0.0074493433 | F17: =E17-E18 -> 0 | G17: =moment_rate!I17-0.005 -> 0.1 | H17: =IF($G17>=4.999,(E17-E18),0) -> 0 | I17: =IF(AND($G17>=I$3,$G17<I$4),$F17,0) -> 0 | J17: =IF(AND($G17>=J$3,$G17<J$4),$F17,0) -> 0 | K17: =IF(AND($G17>=K$3,$G17<K$4),$F17,0) -> 0 | L17: =IF(AND($G17>=L$3,$G17<L$4),$F17,0) -> 0 | M17: =IF(AND($G17>=M$3,$G17<M$4),$F17,0) -> 0 | N17: =IF(AND($G17>=N$3,$G17<N$4),$F17,0) -> 0 | O17: =IF(AND($G17>=O$3,$G17<O$4),$F17,0) -> 0 | P17: =IF(AND($G17>=P$3,$G17<P$4),$F17,0) -> 0 | ... AR17: =IF(AND($G17>=AR$3,$G17<AR$4),$F17,0) -> 0
A18: =A17+0.1 -> 6.15 | B18: =$C18*$H$5 -> 0 | C18: {=INDIRECT(ADDRESS(5,$D18,1,FALSE),FALSE)} -> 0 | D18: =D17+1 -> 20 | E18: =moment_rate!$AC18 -> 0.0074493433 | F18: =E18-E19 -> 0 | G18: =moment_rate!I18-0.005 -> 0.11 | H18: =IF($G18>=4.999,(E18-E19),0) -> 0 | I18: =IF(AND($G18>=I$3,$G18<I$4),$F18,0) -> 0 | J18: =IF(AND($G18>=J$3,$G18<J$4),$F18,0) -> 0 | K18: =IF(AND($G18>=K$3,$G18<K$4),$F18,0) -> 0 | L18: =IF(AND($G18>=L$3,$G18<L$4),$F18,0) -> 0 | M18: =IF(AND($G18>=M$3,$G18<M$4),$F18,0) -> 0 | N18: =IF(AND($G18>=N$3,$G18<N$4),$F18,0) -> 0 | O18: =IF(AND($G18>=O$3,$G18<O$4),$F18,0) -> 0 | P18: =IF(AND($G18>=P$3,$G18<P$4),$F18,0) -> 0 | ... AR18: =IF(AND($G18>=AR$3,$G18<AR$4),$F18,0) -> 0
A19: =A18+0.1 -> 6.25 | B19: =$C19*$H$5 -> 0 | C19: {=INDIRECT(ADDRESS(5,$D19,1,FALSE),FALSE)} -> 0 | D19: =D18+1 -> 21 | E19: =moment_rate!$AC19 -> 0.0074493433 | F19: =E19-E20 -> 0 | G19: =moment_rate!I19-0.005 -> 0.12 | H19: =IF($G19>=4.999,(E19-E20),0) -> 0 | I19: =IF(AND($G19>=I$3,$G19<I$4),$F19,0) -> 0 | J19: =IF(AND($G19>=J$3,$G19<J$4),$F19,0) -> 0 | K19: =IF(AND($G19>=K$3,$G19<K$4),$F19,0) -> 0 | L19: =IF(AND($G19>=L$3,$G19<L$4),$F19,0) -> 0 | M19: =IF(AND($G19>=M$3,$G19<M$4),$F19,0) -> 0 | N19: =IF(AND($G19>=N$3,$G19<N$4),$F19,0) -> 0 | O19: =IF(AND($G19>=O$3,$G19<O$4),$F19,0) -> 0 | P19: =IF(AND($G19>=P$3,$G19<P$4),$F19,0) -> 0 | ... AR19: =IF(AND($G19>=AR$3,$G19<AR$4),$F19,0) -> 0
